2025-07-14 22:45:16,128 - ERROR - database - Error in database session: 500: An error occurred while refreshing token.
Traceback (most recent call last):
  File "C:\Users\Dhanush\FASTAPI\app\api\v1\endpoints\users.py", line 331, in refresh_access_token
     raise HTTPException(
    ...<3 lines>...
    )
fastapi.exceptions.HTTPException: 401: User not found or inactive

During handling of the above exception, another exception occurred:

Traceback (most recent call last):
  File "C:\Users\Dhanush\FASTAPI\app\database\session.py", line 70, in get_db
    yield session
  File "C:\Users\Dhanush\FASTAPI\venv\Lib\site-packages\fastapi\routing.py", line 301, in app
    raw_response = await run_endpoint_function(
                   ^^^^^^^^^^^^^^^^^^^^^^^^^^^^
    ...<3 lines>...
    )
    ^
  File "C:\Users\Dhanush\FASTAPI\venv\Lib\site-packages\fastapi\routing.py", line 212, in run_endpoint_function
    return await dependant.call(**values)
           ^^^^^^^^^^^^^^^^^^^^^^^^^^^^^^
  File "C:\Users\Dhanush\FASTAPI\app\api\v1\endpoints\users.py", line 362, in refresh_access_token
    raise HTTPException(
    ...<2 lines>...
    )
fastapi.exceptions.HTTPException: 500: An error occurred while refreshing token.
2025-07-14 22:45:16,132 - ERROR - database - Error in database session: 500: An error occurred while refreshing token.
Traceback (most recent call last):
  File "C:\Users\Dhanush\FASTAPI\app\api\v1\endpoints\users.py", line 331, in refresh_access_token
     raise HTTPException(
    ...<3 lines>...
    )
fastapi.exceptions.HTTPException: 401: User not found or inactive

During handling of the above exception, another exception occurred:

Traceback (most recent call last):
  File "C:\Users\Dhanush\FASTAPI\app\database\session.py", line 70, in get_db
    yield session
  File "C:\Users\Dhanush\FASTAPI\venv\Lib\site-packages\fastapi\routing.py", line 301, in app
    raw_response = await run_endpoint_function(
                   ^^^^^^^^^^^^^^^^^^^^^^^^^^^^
    ...<3 lines>...
    )
    ^
  File "C:\Users\Dhanush\FASTAPI\venv\Lib\site-packages\fastapi\routing.py", line 212, in run_endpoint_function
    return await dependant.call(**values)
           ^^^^^^^^^^^^^^^^^^^^^^^^^^^^^^
  File "C:\Users\Dhanush\FASTAPI\app\api\v1\endpoints\users.py", line 362, in refresh_access_token
    raise HTTPException(
    ...<2 lines>...
    )
fastapi.exceptions.HTTPException: 500: An error occurred while refreshing token.
2025-07-14 22:45:17,956 - ERROR - database - Error in database session: 401: Could not validate credentials
Traceback (most recent call last):
  File "C:\Users\Dhanush\FASTAPI\app\core\security.py", line 94, in decode_token
    payload = jwt.decode(token, settings.SECRET_KEY, algorithms=[settings.ALGORITHM])
  File "C:\Users\Dhanush\FASTAPI\venv\Lib\site-packages\jose\jwt.py", line 174, in decode
    _validate_claims(
    ~~~~~~~~~~~~~~~~^
        claims,
        ^^^^^^^
    ...<5 lines>...
        options=defaults,
        ^^^^^^^^^^^^^^^^^
    )
    ^
  File "C:\Users\Dhanush\FASTAPI\venv\Lib\site-packages\jose\jwt.py", line 497, in _validate_claims
    _validate_exp(claims, leeway=leeway)
    ~~~~~~~~~~~~~^^^^^^^^^^^^^^^^^^^^^^^
  File "C:\Users\Dhanush\FASTAPI\venv\Lib\site-packages\jose\jwt.py", line 331, in _validate_exp
    raise ExpiredSignatureError("Signature has expired.")
jose.exceptions.ExpiredSignatureError: Signature has expired.

During handling of the above exception, another exception occurred:

Traceback (most recent call last):
  File "C:\Users\Dhanush\FASTAPI\app\core\security.py", line 288, in get_current_user
    payload = decode_token(token)
  File "C:\Users\Dhanush\FASTAPI\app\core\security.py", line 99, in decode_token
    raise JWTError("Could not validate credentials")
jose.exceptions.JWTError: Could not validate credentials

During handling of the above exception, another exception occurred:

Traceback (most recent call last):
  File "C:\Users\Dhanush\FASTAPI\app\database\session.py", line 70, in get_db
    yield session
  File "C:\Users\Dhanush\FASTAPI\venv\Lib\site-packages\fastapi\routing.py", line 291, in app
    solved_result = await solve_dependencies(
                    ^^^^^^^^^^^^^^^^^^^^^^^^^
    ...<6 lines>...
    )
    ^
  File "C:\Users\Dhanush\FASTAPI\venv\Lib\site-packages\fastapi\dependencies\utils.py", line 638, in solve_dependencies
    solved = await call(**solved_result.values)
             ^^^^^^^^^^^^^^^^^^^^^^^^^^^^^^^^^^
  File "C:\Users\Dhanush\FASTAPI\app\core\security.py", line 337, in get_current_user
    raise credentials_exception
fastapi.exceptions.HTTPException: 401: Could not validate credentials
