2025-07-18 04:53:09,608 - ERROR - database - Error in database session: 500: Failed to update order: 404: Order not found with provided ID
Traceback (most recent call last):
  File "C:\Users\Dhanush\FASTAPI\app\api\v1\endpoints\orders.py", line 4135, in service_provider_order_update
    raise HTTPException(status_code=404, detail="Order not found with provided ID")
fastapi.exceptions.HTTPException: 404: Order not found with provided ID

During handling of the above exception, another exception occurred:

Traceback (most recent call last):
  File "C:\Users\Dhanush\FASTAPI\app\database\session.py", line 70, in get_db
    yield session
  File "C:\Users\Dhanush\FASTAPI\venv\Lib\site-packages\fastapi\routing.py", line 301, in app
    raw_response = await run_endpoint_function(
                   ^^^^^^^^^^^^^^^^^^^^^^^^^^^^
    ...<3 lines>...
    )
    ^
  File "C:\Users\Dhanush\FASTAPI\venv\Lib\site-packages\fastapi\routing.py", line 212, in run_endpoint_function
    return await dependant.call(**values)
           ^^^^^^^^^^^^^^^^^^^^^^^^^^^^^^
  File "C:\Users\Dhanush\FASTAPI\app\api\v1\endpoints\orders.py", line 4821, in service_provider_order_update
    raise HTTPException(status_code=500, detail=f"Failed to update order: {str(e)}")
fastapi.exceptions.HTTPException: 500: Failed to update order: 404: Order not found with provided ID
2025-07-20 23:39:22,834 - ERROR - database - Error in database session: 401: Could not validate credentials
Traceback (most recent call last):
  File "C:\Users\Dhanush\FASTAPI\app\core\security.py", line 94, in decode_token
    payload = jwt.decode(token, settings.SECRET_KEY, algorithms=[settings.ALGORITHM])
  File "C:\Users\Dhanush\FASTAPI\venv\Lib\site-packages\jose\jwt.py", line 174, in decode
    _validate_claims(
    ~~~~~~~~~~~~~~~~^
        claims,
        ^^^^^^^
    ...<5 lines>...
        options=defaults,
        ^^^^^^^^^^^^^^^^^
    )
    ^
  File "C:\Users\Dhanush\FASTAPI\venv\Lib\site-packages\jose\jwt.py", line 497, in _validate_claims
    _validate_exp(claims, leeway=leeway)
    ~~~~~~~~~~~~~^^^^^^^^^^^^^^^^^^^^^^^
  File "C:\Users\Dhanush\FASTAPI\venv\Lib\site-packages\jose\jwt.py", line 331, in _validate_exp
    raise ExpiredSignatureError("Signature has expired.")
jose.exceptions.ExpiredSignatureError: Signature has expired.

During handling of the above exception, another exception occurred:

Traceback (most recent call last):
  File "C:\Users\Dhanush\FASTAPI\app\core\security.py", line 444, in get_user_from_service_or_user_token
    payload = decode_token(token)
  File "C:\Users\Dhanush\FASTAPI\app\core\security.py", line 99, in decode_token
    raise JWTError("Could not validate credentials")
jose.exceptions.JWTError: Could not validate credentials

During handling of the above exception, another exception occurred:

Traceback (most recent call last):
  File "C:\Users\Dhanush\FASTAPI\app\database\session.py", line 70, in get_db
    yield session
  File "C:\Users\Dhanush\FASTAPI\venv\Lib\site-packages\fastapi\routing.py", line 291, in app
    solved_result = await solve_dependencies(
                    ^^^^^^^^^^^^^^^^^^^^^^^^^
    ...<6 lines>...
    )
    ^
  File "C:\Users\Dhanush\FASTAPI\venv\Lib\site-packages\fastapi\dependencies\utils.py", line 638, in solve_dependencies
    solved = await call(**solved_result.values)
             ^^^^^^^^^^^^^^^^^^^^^^^^^^^^^^^^^^
  File "C:\Users\Dhanush\FASTAPI\app\core\security.py", line 497, in get_user_from_service_or_user_token
    raise HTTPException(
    ...<3 lines>...
    )
fastapi.exceptions.HTTPException: 401: Could not validate credentials
2025-07-20 23:39:22,906 - ERROR - database - Error in database session: 401: Could not validate credentials
Traceback (most recent call last):
  File "C:\Users\Dhanush\FASTAPI\app\core\security.py", line 94, in decode_token
    payload = jwt.decode(token, settings.SECRET_KEY, algorithms=[settings.ALGORITHM])
  File "C:\Users\Dhanush\FASTAPI\venv\Lib\site-packages\jose\jwt.py", line 174, in decode
    _validate_claims(
    ~~~~~~~~~~~~~~~~^
        claims,
        ^^^^^^^
    ...<5 lines>...
        options=defaults,
        ^^^^^^^^^^^^^^^^^
    )
    ^
  File "C:\Users\Dhanush\FASTAPI\venv\Lib\site-packages\jose\jwt.py", line 497, in _validate_claims
    _validate_exp(claims, leeway=leeway)
    ~~~~~~~~~~~~~^^^^^^^^^^^^^^^^^^^^^^^
  File "C:\Users\Dhanush\FASTAPI\venv\Lib\site-packages\jose\jwt.py", line 331, in _validate_exp
    raise ExpiredSignatureError("Signature has expired.")
jose.exceptions.ExpiredSignatureError: Signature has expired.

During handling of the above exception, another exception occurred:

Traceback (most recent call last):
  File "C:\Users\Dhanush\FASTAPI\app\core\security.py", line 444, in get_user_from_service_or_user_token
    payload = decode_token(token)
  File "C:\Users\Dhanush\FASTAPI\app\core\security.py", line 99, in decode_token
    raise JWTError("Could not validate credentials")
jose.exceptions.JWTError: Could not validate credentials

During handling of the above exception, another exception occurred:

Traceback (most recent call last):
  File "C:\Users\Dhanush\FASTAPI\app\database\session.py", line 70, in get_db
    yield session
  File "C:\Users\Dhanush\FASTAPI\venv\Lib\site-packages\fastapi\routing.py", line 291, in app
    solved_result = await solve_dependencies(
                    ^^^^^^^^^^^^^^^^^^^^^^^^^
    ...<6 lines>...
    )
    ^
  File "C:\Users\Dhanush\FASTAPI\venv\Lib\site-packages\fastapi\dependencies\utils.py", line 638, in solve_dependencies
    solved = await call(**solved_result.values)
             ^^^^^^^^^^^^^^^^^^^^^^^^^^^^^^^^^^
  File "C:\Users\Dhanush\FASTAPI\app\core\security.py", line 497, in get_user_from_service_or_user_token
    raise HTTPException(
    ...<3 lines>...
    )
fastapi.exceptions.HTTPException: 401: Could not validate credentials
