2025-07-18 04:53:09,608 - ERROR - database - Error in database session: 500: Failed to update order: 404: Order not found with provided ID
Traceback (most recent call last):
  File "C:\Users\Dhanush\FASTAPI\app\api\v1\endpoints\orders.py", line 4135, in service_provider_order_update
    raise HTTPException(status_code=404, detail="Order not found with provided ID")
fastapi.exceptions.HTTPException: 404: Order not found with provided ID

During handling of the above exception, another exception occurred:

Traceback (most recent call last):
  File "C:\Users\Dhanush\FASTAPI\app\database\session.py", line 70, in get_db
    yield session
  File "C:\Users\Dhanush\FASTAPI\venv\Lib\site-packages\fastapi\routing.py", line 301, in app
    raw_response = await run_endpoint_function(
                   ^^^^^^^^^^^^^^^^^^^^^^^^^^^^
    ...<3 lines>...
    )
    ^
  File "C:\Users\Dhanush\FASTAPI\venv\Lib\site-packages\fastapi\routing.py", line 212, in run_endpoint_function
    return await dependant.call(**values)
           ^^^^^^^^^^^^^^^^^^^^^^^^^^^^^^
  File "C:\Users\Dhanush\FASTAPI\app\api\v1\endpoints\orders.py", line 4821, in service_provider_order_update
    raise HTTPException(status_code=500, detail=f"Failed to update order: {str(e)}")
fastapi.exceptions.HTTPException: 500: Failed to update order: 404: Order not found with provided ID
