2025-07-08 21:13:53,698 - ERROR - error - Error in place_order: Failed to process order: name 'user_data_to_cache' is not defined
Traceback (most recent call last):
  File "C:\Users\Dhanush\FASTAPI\app\services\order_processing.py", line 337, in process_new_order_ultra_optimized
    f"user_data:{user_type}:{user_id}": user_data_to_cache
                                        ^^^^^^^^^^^^^^^^^^
NameError: name 'user_data_to_cache' is not defined

During handling of the above exception, another exception occurred:

Traceback (most recent call last):
  File "C:\Users\Dhanush\FASTAPI\app\api\v1\endpoints\orders.py", line 500, in place_order
    processed_order_data = await process_new_order(
                           ^^^^^^^^^^^^^^^^^^^^^^^^
    ...<6 lines>...
    )
    ^
  File "C:\Users\Dhanush\FASTAPI\app\services\order_processing.py", line 362, in process_new_order_ultra_optimized
    raise OrderProcessingError(f"Failed to process order: {str(e)}")
app.services.order_processing.OrderProcessingError: Failed to process order: name 'user_data_to_cache' is not defined
