2025-07-18 04:47:25,890 - INFO - app.core.security - [Redis] Connected to localhost (127.0.0.1):6380
2025-07-18 04:47:25,892 - INFO - app.core.security - [Redis] AOF persistence already enabled.
2025-07-18 04:49:05,838 - INFO - app.core.security - [Redis] Connection closed successfully.
2025-07-18 04:52:01,646 - INFO - app.core.security - [Redis] Connected to localhost (127.0.0.1):6380
2025-07-18 04:52:01,648 - INFO - app.core.security - [Redis] AOF persistence already enabled.
2025-07-18 04:52:20,335 - INFO - app.core.security - LOGOUT: user_id=1, email=dhanush777ss@gmail.com, user_type=demo, time=2025-07-18T11:52:20.335677
2025-07-18 04:52:22,821 - INFO - app.core.security - LOGIN: user_id=4, email=dhanush777ss@gmail.com, user_type=live, time=2025-07-18T11:52:22.821053
2025-07-18 04:54:13,563 - INFO - app.core.security - [Redis] Connection closed successfully.
2025-07-18 05:07:18,213 - INFO - app.core.security - [Redis] Connected to localhost (127.0.0.1):6380
2025-07-18 05:07:18,215 - INFO - app.core.security - [Redis] AOF persistence already enabled.
2025-07-18 05:08:01,322 - INFO - app.core.security - [Redis] Connection closed successfully.
2025-07-18 05:10:25,120 - INFO - app.core.security - [Redis] Connected to localhost (127.0.0.1):6380
2025-07-18 05:10:25,122 - INFO - app.core.security - [Redis] AOF persistence already enabled.
2025-07-18 05:11:10,155 - INFO - app.core.security - [Redis] Connection closed successfully.
2025-07-20 20:56:11,083 - ERROR - app.core.security - [Redis] Connection failed: Error Multiple exceptions: [Errno 10061] Connect call failed ('::1', 6380, 0, 0), [Errno 10061] Connect call failed ('127.0.0.1', 6380) connecting to localhost:6380.
Traceback (most recent call last):
  File "C:\Users\Dhanush\FASTAPI\venv\Lib\site-packages\redis\asyncio\connection.py", line 302, in connect_check_health
    await self.retry.call_with_retry(
        lambda: self._connect(), lambda error: self.disconnect()
    )
  File "C:\Users\Dhanush\FASTAPI\venv\Lib\site-packages\redis\asyncio\retry.py", line 71, in call_with_retry
    return await do()
           ^^^^^^^^^^
  File "C:\Users\Dhanush\FASTAPI\venv\Lib\site-packages\redis\asyncio\connection.py", line 755, in _connect
    reader, writer = await asyncio.open_connection(
                     ^^^^^^^^^^^^^^^^^^^^^^^^^^^^^^
        **self._connection_arguments()
        ^^^^^^^^^^^^^^^^^^^^^^^^^^^^^^
    )
    ^
  File "C:\Users\Dhanush\AppData\Local\Programs\Python\Python313\Lib\asyncio\streams.py", line 48, in open_connection
    transport, _ = await loop.create_connection(
                   ^^^^^^^^^^^^^^^^^^^^^^^^^^^^^
        lambda: protocol, host, port, **kwds)
        ^^^^^^^^^^^^^^^^^^^^^^^^^^^^^^^^^^^^^
  File "C:\Users\Dhanush\AppData\Local\Programs\Python\Python313\Lib\asyncio\base_events.py", line 1174, in create_connection
    raise OSError('Multiple exceptions: {}'.format(
        ', '.join(str(exc) for exc in exceptions)))
OSError: Multiple exceptions: [Errno 10061] Connect call failed ('::1', 6380, 0, 0), [Errno 10061] Connect call failed ('127.0.0.1', 6380)

During handling of the above exception, another exception occurred:

Traceback (most recent call last):
  File "C:\Users\Dhanush\FASTAPI\app\core\security.py", line 206, in connect_to_redis
    await client.ping()
  File "C:\Users\Dhanush\FASTAPI\venv\Lib\site-packages\redis\asyncio\client.py", line 672, in execute_command
    conn = self.connection or await pool.get_connection()
                              ^^^^^^^^^^^^^^^^^^^^^^^^^^^
  File "C:\Users\Dhanush\FASTAPI\venv\Lib\site-packages\redis\asyncio\connection.py", line 1141, in get_connection
    await self.ensure_connection(connection)
  File "C:\Users\Dhanush\FASTAPI\venv\Lib\site-packages\redis\asyncio\connection.py", line 1174, in ensure_connection
    await connection.connect()
  File "C:\Users\Dhanush\FASTAPI\venv\Lib\site-packages\redis\asyncio\connection.py", line 296, in connect
    await self.connect_check_health(check_health=True)
  File "C:\Users\Dhanush\FASTAPI\venv\Lib\site-packages\redis\asyncio\connection.py", line 310, in connect_check_health
    raise ConnectionError(self._error_message(e))
redis.exceptions.ConnectionError: Error Multiple exceptions: [Errno 10061] Connect call failed ('::1', 6380, 0, 0), [Errno 10061] Connect call failed ('127.0.0.1', 6380) connecting to localhost:6380.
2025-07-20 22:17:58,827 - ERROR - app.core.security - [Redis] Connection failed: Error Multiple exceptions: [Errno 10061] Connect call failed ('::1', 6380, 0, 0), [Errno 10061] Connect call failed ('127.0.0.1', 6380) connecting to localhost:6380.
Traceback (most recent call last):
  File "C:\Users\Dhanush\FASTAPI\venv\Lib\site-packages\redis\asyncio\connection.py", line 302, in connect_check_health
    await self.retry.call_with_retry(
        lambda: self._connect(), lambda error: self.disconnect()
    )
  File "C:\Users\Dhanush\FASTAPI\venv\Lib\site-packages\redis\asyncio\retry.py", line 71, in call_with_retry
    return await do()
           ^^^^^^^^^^
  File "C:\Users\Dhanush\FASTAPI\venv\Lib\site-packages\redis\asyncio\connection.py", line 755, in _connect
    reader, writer = await asyncio.open_connection(
                     ^^^^^^^^^^^^^^^^^^^^^^^^^^^^^^
        **self._connection_arguments()
        ^^^^^^^^^^^^^^^^^^^^^^^^^^^^^^
    )
    ^
  File "C:\Users\Dhanush\AppData\Local\Programs\Python\Python313\Lib\asyncio\streams.py", line 48, in open_connection
    transport, _ = await loop.create_connection(
                   ^^^^^^^^^^^^^^^^^^^^^^^^^^^^^
        lambda: protocol, host, port, **kwds)
        ^^^^^^^^^^^^^^^^^^^^^^^^^^^^^^^^^^^^^
  File "C:\Users\Dhanush\AppData\Local\Programs\Python\Python313\Lib\asyncio\base_events.py", line 1174, in create_connection
    raise OSError('Multiple exceptions: {}'.format(
        ', '.join(str(exc) for exc in exceptions)))
OSError: Multiple exceptions: [Errno 10061] Connect call failed ('::1', 6380, 0, 0), [Errno 10061] Connect call failed ('127.0.0.1', 6380)

During handling of the above exception, another exception occurred:

Traceback (most recent call last):
  File "C:\Users\Dhanush\FASTAPI\app\core\security.py", line 206, in connect_to_redis
    await client.ping()
  File "C:\Users\Dhanush\FASTAPI\venv\Lib\site-packages\redis\asyncio\client.py", line 672, in execute_command
    conn = self.connection or await pool.get_connection()
                              ^^^^^^^^^^^^^^^^^^^^^^^^^^^
  File "C:\Users\Dhanush\FASTAPI\venv\Lib\site-packages\redis\asyncio\connection.py", line 1141, in get_connection
    await self.ensure_connection(connection)
  File "C:\Users\Dhanush\FASTAPI\venv\Lib\site-packages\redis\asyncio\connection.py", line 1174, in ensure_connection
    await connection.connect()
  File "C:\Users\Dhanush\FASTAPI\venv\Lib\site-packages\redis\asyncio\connection.py", line 296, in connect
    await self.connect_check_health(check_health=True)
  File "C:\Users\Dhanush\FASTAPI\venv\Lib\site-packages\redis\asyncio\connection.py", line 310, in connect_check_health
    raise ConnectionError(self._error_message(e))
redis.exceptions.ConnectionError: Error Multiple exceptions: [Errno 10061] Connect call failed ('::1', 6380, 0, 0), [Errno 10061] Connect call failed ('127.0.0.1', 6380) connecting to localhost:6380.
2025-07-20 22:22:53,271 - ERROR - app.core.security - [Redis] Connection failed: Error Multiple exceptions: [Errno 10061] Connect call failed ('::1', 6380, 0, 0), [Errno 10061] Connect call failed ('127.0.0.1', 6380) connecting to localhost:6380.
Traceback (most recent call last):
  File "C:\Users\Dhanush\FASTAPI\venv\Lib\site-packages\redis\asyncio\connection.py", line 302, in connect_check_health
    await self.retry.call_with_retry(
        lambda: self._connect(), lambda error: self.disconnect()
    )
  File "C:\Users\Dhanush\FASTAPI\venv\Lib\site-packages\redis\asyncio\retry.py", line 71, in call_with_retry
    return await do()
           ^^^^^^^^^^
  File "C:\Users\Dhanush\FASTAPI\venv\Lib\site-packages\redis\asyncio\connection.py", line 755, in _connect
    reader, writer = await asyncio.open_connection(
                     ^^^^^^^^^^^^^^^^^^^^^^^^^^^^^^
        **self._connection_arguments()
        ^^^^^^^^^^^^^^^^^^^^^^^^^^^^^^
    )
    ^
  File "C:\Users\Dhanush\AppData\Local\Programs\Python\Python313\Lib\asyncio\streams.py", line 48, in open_connection
    transport, _ = await loop.create_connection(
                   ^^^^^^^^^^^^^^^^^^^^^^^^^^^^^
        lambda: protocol, host, port, **kwds)
        ^^^^^^^^^^^^^^^^^^^^^^^^^^^^^^^^^^^^^
  File "C:\Users\Dhanush\AppData\Local\Programs\Python\Python313\Lib\asyncio\base_events.py", line 1174, in create_connection
    raise OSError('Multiple exceptions: {}'.format(
        ', '.join(str(exc) for exc in exceptions)))
OSError: Multiple exceptions: [Errno 10061] Connect call failed ('::1', 6380, 0, 0), [Errno 10061] Connect call failed ('127.0.0.1', 6380)

During handling of the above exception, another exception occurred:

Traceback (most recent call last):
  File "C:\Users\Dhanush\FASTAPI\app\core\security.py", line 206, in connect_to_redis
    await client.ping()
  File "C:\Users\Dhanush\FASTAPI\venv\Lib\site-packages\redis\asyncio\client.py", line 672, in execute_command
    conn = self.connection or await pool.get_connection()
                              ^^^^^^^^^^^^^^^^^^^^^^^^^^^
  File "C:\Users\Dhanush\FASTAPI\venv\Lib\site-packages\redis\asyncio\connection.py", line 1141, in get_connection
    await self.ensure_connection(connection)
  File "C:\Users\Dhanush\FASTAPI\venv\Lib\site-packages\redis\asyncio\connection.py", line 1174, in ensure_connection
    await connection.connect()
  File "C:\Users\Dhanush\FASTAPI\venv\Lib\site-packages\redis\asyncio\connection.py", line 296, in connect
    await self.connect_check_health(check_health=True)
  File "C:\Users\Dhanush\FASTAPI\venv\Lib\site-packages\redis\asyncio\connection.py", line 310, in connect_check_health
    raise ConnectionError(self._error_message(e))
redis.exceptions.ConnectionError: Error Multiple exceptions: [Errno 10061] Connect call failed ('::1', 6380, 0, 0), [Errno 10061] Connect call failed ('127.0.0.1', 6380) connecting to localhost:6380.
2025-07-20 22:25:44,706 - ERROR - app.core.security - [Redis] Connection failed: Error Multiple exceptions: [Errno 10061] Connect call failed ('::1', 6380, 0, 0), [Errno 10061] Connect call failed ('127.0.0.1', 6380) connecting to localhost:6380.
Traceback (most recent call last):
  File "C:\Users\Dhanush\FASTAPI\venv\Lib\site-packages\redis\asyncio\connection.py", line 302, in connect_check_health
    await self.retry.call_with_retry(
        lambda: self._connect(), lambda error: self.disconnect()
    )
  File "C:\Users\Dhanush\FASTAPI\venv\Lib\site-packages\redis\asyncio\retry.py", line 71, in call_with_retry
    return await do()
           ^^^^^^^^^^
  File "C:\Users\Dhanush\FASTAPI\venv\Lib\site-packages\redis\asyncio\connection.py", line 755, in _connect
    reader, writer = await asyncio.open_connection(
                     ^^^^^^^^^^^^^^^^^^^^^^^^^^^^^^
        **self._connection_arguments()
        ^^^^^^^^^^^^^^^^^^^^^^^^^^^^^^
    )
    ^
  File "C:\Users\Dhanush\AppData\Local\Programs\Python\Python313\Lib\asyncio\streams.py", line 48, in open_connection
    transport, _ = await loop.create_connection(
                   ^^^^^^^^^^^^^^^^^^^^^^^^^^^^^
        lambda: protocol, host, port, **kwds)
        ^^^^^^^^^^^^^^^^^^^^^^^^^^^^^^^^^^^^^
  File "C:\Users\Dhanush\AppData\Local\Programs\Python\Python313\Lib\asyncio\base_events.py", line 1174, in create_connection
    raise OSError('Multiple exceptions: {}'.format(
        ', '.join(str(exc) for exc in exceptions)))
OSError: Multiple exceptions: [Errno 10061] Connect call failed ('::1', 6380, 0, 0), [Errno 10061] Connect call failed ('127.0.0.1', 6380)

During handling of the above exception, another exception occurred:

Traceback (most recent call last):
  File "C:\Users\Dhanush\FASTAPI\app\core\security.py", line 206, in connect_to_redis
    await client.ping()
  File "C:\Users\Dhanush\FASTAPI\venv\Lib\site-packages\redis\asyncio\client.py", line 672, in execute_command
    conn = self.connection or await pool.get_connection()
                              ^^^^^^^^^^^^^^^^^^^^^^^^^^^
  File "C:\Users\Dhanush\FASTAPI\venv\Lib\site-packages\redis\asyncio\connection.py", line 1141, in get_connection
    await self.ensure_connection(connection)
  File "C:\Users\Dhanush\FASTAPI\venv\Lib\site-packages\redis\asyncio\connection.py", line 1174, in ensure_connection
    await connection.connect()
  File "C:\Users\Dhanush\FASTAPI\venv\Lib\site-packages\redis\asyncio\connection.py", line 296, in connect
    await self.connect_check_health(check_health=True)
  File "C:\Users\Dhanush\FASTAPI\venv\Lib\site-packages\redis\asyncio\connection.py", line 310, in connect_check_health
    raise ConnectionError(self._error_message(e))
redis.exceptions.ConnectionError: Error Multiple exceptions: [Errno 10061] Connect call failed ('::1', 6380, 0, 0), [Errno 10061] Connect call failed ('127.0.0.1', 6380) connecting to localhost:6380.
2025-07-20 22:37:48,099 - ERROR - app.core.security - [Redis] Connection failed: Error Multiple exceptions: [Errno 10061] Connect call failed ('::1', 6380, 0, 0), [Errno 10061] Connect call failed ('127.0.0.1', 6380) connecting to localhost:6380.
Traceback (most recent call last):
  File "C:\Users\Dhanush\FASTAPI\venv\Lib\site-packages\redis\asyncio\connection.py", line 302, in connect_check_health
    await self.retry.call_with_retry(
        lambda: self._connect(), lambda error: self.disconnect()
    )
  File "C:\Users\Dhanush\FASTAPI\venv\Lib\site-packages\redis\asyncio\retry.py", line 71, in call_with_retry
    return await do()
           ^^^^^^^^^^
  File "C:\Users\Dhanush\FASTAPI\venv\Lib\site-packages\redis\asyncio\connection.py", line 755, in _connect
    reader, writer = await asyncio.open_connection(
                     ^^^^^^^^^^^^^^^^^^^^^^^^^^^^^^
        **self._connection_arguments()
        ^^^^^^^^^^^^^^^^^^^^^^^^^^^^^^
    )
    ^
  File "C:\Users\Dhanush\AppData\Local\Programs\Python\Python313\Lib\asyncio\streams.py", line 48, in open_connection
    transport, _ = await loop.create_connection(
                   ^^^^^^^^^^^^^^^^^^^^^^^^^^^^^
        lambda: protocol, host, port, **kwds)
        ^^^^^^^^^^^^^^^^^^^^^^^^^^^^^^^^^^^^^
  File "C:\Users\Dhanush\AppData\Local\Programs\Python\Python313\Lib\asyncio\base_events.py", line 1174, in create_connection
    raise OSError('Multiple exceptions: {}'.format(
        ', '.join(str(exc) for exc in exceptions)))
OSError: Multiple exceptions: [Errno 10061] Connect call failed ('::1', 6380, 0, 0), [Errno 10061] Connect call failed ('127.0.0.1', 6380)

During handling of the above exception, another exception occurred:

Traceback (most recent call last):
  File "C:\Users\Dhanush\FASTAPI\app\core\security.py", line 206, in connect_to_redis
    await client.ping()
  File "C:\Users\Dhanush\FASTAPI\venv\Lib\site-packages\redis\asyncio\client.py", line 672, in execute_command
    conn = self.connection or await pool.get_connection()
                              ^^^^^^^^^^^^^^^^^^^^^^^^^^^
  File "C:\Users\Dhanush\FASTAPI\venv\Lib\site-packages\redis\asyncio\connection.py", line 1141, in get_connection
    await self.ensure_connection(connection)
  File "C:\Users\Dhanush\FASTAPI\venv\Lib\site-packages\redis\asyncio\connection.py", line 1174, in ensure_connection
    await connection.connect()
  File "C:\Users\Dhanush\FASTAPI\venv\Lib\site-packages\redis\asyncio\connection.py", line 296, in connect
    await self.connect_check_health(check_health=True)
  File "C:\Users\Dhanush\FASTAPI\venv\Lib\site-packages\redis\asyncio\connection.py", line 310, in connect_check_health
    raise ConnectionError(self._error_message(e))
redis.exceptions.ConnectionError: Error Multiple exceptions: [Errno 10061] Connect call failed ('::1', 6380, 0, 0), [Errno 10061] Connect call failed ('127.0.0.1', 6380) connecting to localhost:6380.
2025-07-20 22:39:54,718 - ERROR - app.core.security - [Redis] Connection failed: Error Multiple exceptions: [Errno 10061] Connect call failed ('::1', 6380, 0, 0), [Errno 10061] Connect call failed ('127.0.0.1', 6380) connecting to localhost:6380.
Traceback (most recent call last):
  File "C:\Users\Dhanush\FASTAPI\venv\Lib\site-packages\redis\asyncio\connection.py", line 302, in connect_check_health
    await self.retry.call_with_retry(
        lambda: self._connect(), lambda error: self.disconnect()
    )
  File "C:\Users\Dhanush\FASTAPI\venv\Lib\site-packages\redis\asyncio\retry.py", line 71, in call_with_retry
    return await do()
           ^^^^^^^^^^
  File "C:\Users\Dhanush\FASTAPI\venv\Lib\site-packages\redis\asyncio\connection.py", line 755, in _connect
    reader, writer = await asyncio.open_connection(
                     ^^^^^^^^^^^^^^^^^^^^^^^^^^^^^^
        **self._connection_arguments()
        ^^^^^^^^^^^^^^^^^^^^^^^^^^^^^^
    )
    ^
  File "C:\Users\Dhanush\AppData\Local\Programs\Python\Python313\Lib\asyncio\streams.py", line 48, in open_connection
    transport, _ = await loop.create_connection(
                   ^^^^^^^^^^^^^^^^^^^^^^^^^^^^^
        lambda: protocol, host, port, **kwds)
        ^^^^^^^^^^^^^^^^^^^^^^^^^^^^^^^^^^^^^
  File "C:\Users\Dhanush\AppData\Local\Programs\Python\Python313\Lib\asyncio\base_events.py", line 1174, in create_connection
    raise OSError('Multiple exceptions: {}'.format(
        ', '.join(str(exc) for exc in exceptions)))
OSError: Multiple exceptions: [Errno 10061] Connect call failed ('::1', 6380, 0, 0), [Errno 10061] Connect call failed ('127.0.0.1', 6380)

During handling of the above exception, another exception occurred:

Traceback (most recent call last):
  File "C:\Users\Dhanush\FASTAPI\app\core\security.py", line 206, in connect_to_redis
    await client.ping()
  File "C:\Users\Dhanush\FASTAPI\venv\Lib\site-packages\redis\asyncio\client.py", line 672, in execute_command
    conn = self.connection or await pool.get_connection()
                              ^^^^^^^^^^^^^^^^^^^^^^^^^^^
  File "C:\Users\Dhanush\FASTAPI\venv\Lib\site-packages\redis\asyncio\connection.py", line 1141, in get_connection
    await self.ensure_connection(connection)
  File "C:\Users\Dhanush\FASTAPI\venv\Lib\site-packages\redis\asyncio\connection.py", line 1174, in ensure_connection
    await connection.connect()
  File "C:\Users\Dhanush\FASTAPI\venv\Lib\site-packages\redis\asyncio\connection.py", line 296, in connect
    await self.connect_check_health(check_health=True)
  File "C:\Users\Dhanush\FASTAPI\venv\Lib\site-packages\redis\asyncio\connection.py", line 310, in connect_check_health
    raise ConnectionError(self._error_message(e))
redis.exceptions.ConnectionError: Error Multiple exceptions: [Errno 10061] Connect call failed ('::1', 6380, 0, 0), [Errno 10061] Connect call failed ('127.0.0.1', 6380) connecting to localhost:6380.
2025-07-20 22:41:19,835 - INFO - app.core.security - [Redis] Connected to localhost (127.0.0.1):6380
2025-07-20 22:41:19,837 - WARNING - app.core.security - [Redis] AOF persistence not enabled. Enabling now...
2025-07-20 22:41:19,842 - INFO - app.core.security - [Redis] AOF persistence enabled with appendfsync=everysec.
2025-07-20 22:42:30,396 - INFO - app.core.security - [Redis] Connection closed successfully.
2025-07-20 22:42:32,850 - INFO - app.core.security - [Redis] Connected to localhost (127.0.0.1):6380
2025-07-20 22:42:32,852 - INFO - app.core.security - [Redis] AOF persistence already enabled.
2025-07-20 22:42:55,805 - INFO - app.core.security - [Redis] Connection closed successfully.
2025-07-20 22:42:58,476 - INFO - app.core.security - [Redis] Connected to localhost (127.0.0.1):6380
2025-07-20 22:42:58,479 - INFO - app.core.security - [Redis] AOF persistence already enabled.
2025-07-20 22:44:00,279 - INFO - app.core.security - [Redis] Connection closed successfully.
2025-07-20 22:44:02,654 - INFO - app.core.security - [Redis] Connected to localhost (127.0.0.1):6380
2025-07-20 22:44:02,656 - INFO - app.core.security - [Redis] AOF persistence already enabled.
2025-07-20 22:52:20,348 - INFO - app.core.security - [Redis] Connection closed successfully.
2025-07-20 23:38:56,028 - INFO - app.core.security - [Redis] Connected to localhost (127.0.0.1):6380
2025-07-20 23:38:56,035 - INFO - app.core.security - [Redis] AOF persistence already enabled.
2025-07-20 23:39:22,821 - ERROR - app.core.security - Authentication error in get_user_from_service_or_user_token: Could not validate credentials
Traceback (most recent call last):
  File "C:\Users\Dhanush\FASTAPI\app\core\security.py", line 94, in decode_token
    payload = jwt.decode(token, settings.SECRET_KEY, algorithms=[settings.ALGORITHM])
  File "C:\Users\Dhanush\FASTAPI\venv\Lib\site-packages\jose\jwt.py", line 174, in decode
    _validate_claims(
    ~~~~~~~~~~~~~~~~^
        claims,
        ^^^^^^^
    ...<5 lines>...
        options=defaults,
        ^^^^^^^^^^^^^^^^^
    )
    ^
  File "C:\Users\Dhanush\FASTAPI\venv\Lib\site-packages\jose\jwt.py", line 497, in _validate_claims
    _validate_exp(claims, leeway=leeway)
    ~~~~~~~~~~~~~^^^^^^^^^^^^^^^^^^^^^^^
  File "C:\Users\Dhanush\FASTAPI\venv\Lib\site-packages\jose\jwt.py", line 331, in _validate_exp
    raise ExpiredSignatureError("Signature has expired.")
jose.exceptions.ExpiredSignatureError: Signature has expired.

During handling of the above exception, another exception occurred:

Traceback (most recent call last):
  File "C:\Users\Dhanush\FASTAPI\app\core\security.py", line 444, in get_user_from_service_or_user_token
    payload = decode_token(token)
  File "C:\Users\Dhanush\FASTAPI\app\core\security.py", line 99, in decode_token
    raise JWTError("Could not validate credentials")
jose.exceptions.JWTError: Could not validate credentials
2025-07-20 23:39:22,903 - ERROR - app.core.security - Authentication error in get_user_from_service_or_user_token: Could not validate credentials
Traceback (most recent call last):
  File "C:\Users\Dhanush\FASTAPI\app\core\security.py", line 94, in decode_token
    payload = jwt.decode(token, settings.SECRET_KEY, algorithms=[settings.ALGORITHM])
  File "C:\Users\Dhanush\FASTAPI\venv\Lib\site-packages\jose\jwt.py", line 174, in decode
    _validate_claims(
    ~~~~~~~~~~~~~~~~^
        claims,
        ^^^^^^^
    ...<5 lines>...
        options=defaults,
        ^^^^^^^^^^^^^^^^^
    )
    ^
  File "C:\Users\Dhanush\FASTAPI\venv\Lib\site-packages\jose\jwt.py", line 497, in _validate_claims
    _validate_exp(claims, leeway=leeway)
    ~~~~~~~~~~~~~^^^^^^^^^^^^^^^^^^^^^^^
  File "C:\Users\Dhanush\FASTAPI\venv\Lib\site-packages\jose\jwt.py", line 331, in _validate_exp
    raise ExpiredSignatureError("Signature has expired.")
jose.exceptions.ExpiredSignatureError: Signature has expired.

During handling of the above exception, another exception occurred:

Traceback (most recent call last):
  File "C:\Users\Dhanush\FASTAPI\app\core\security.py", line 444, in get_user_from_service_or_user_token
    payload = decode_token(token)
  File "C:\Users\Dhanush\FASTAPI\app\core\security.py", line 99, in decode_token
    raise JWTError("Could not validate credentials")
jose.exceptions.JWTError: Could not validate credentials
2025-07-20 23:40:01,403 - INFO - app.core.security - [Redis] Connection closed successfully.
2025-07-21 01:28:34,703 - INFO - app.core.security - [Redis] Connected to localhost (127.0.0.1):6380
2025-07-21 01:28:34,705 - INFO - app.core.security - [Redis] AOF persistence already enabled.
2025-07-21 01:32:23,399 - INFO - app.core.security - [Redis] Connection closed successfully.
2025-07-21 01:46:04,595 - INFO - app.core.security - [Redis] Connected to localhost (127.0.0.1):6380
2025-07-21 01:46:04,597 - INFO - app.core.security - [Redis] AOF persistence already enabled.
2025-07-21 01:46:17,013 - INFO - app.core.security - [Redis] Connection closed successfully.
2025-07-21 01:50:34,034 - INFO - app.core.security - [Redis] Connected to localhost (127.0.0.1):6380
2025-07-21 01:50:34,036 - INFO - app.core.security - [Redis] AOF persistence already enabled.
2025-07-21 01:50:40,461 - INFO - app.core.security - LOGIN: user_id=4, email=dhanush777ss@gmail.com, user_type=live, time=2025-07-21T08:50:40.461267
2025-07-21 02:00:59,735 - INFO - app.core.security - [Redis] Connection closed successfully.
2025-07-21 05:18:36,689 - INFO - app.core.security - [Redis] Connected to localhost (127.0.0.1):6380
2025-07-21 05:18:36,691 - INFO - app.core.security - [Redis] AOF persistence already enabled.
2025-07-21 05:29:12,665 - INFO - app.core.security - [Redis] Connection closed successfully.
2025-07-21 05:34:35,274 - INFO - app.core.security - [Redis] Connected to localhost (127.0.0.1):6380
2025-07-21 05:34:35,276 - INFO - app.core.security - [Redis] AOF persistence already enabled.
2025-07-21 05:37:56,202 - INFO - app.core.security - [Redis] Connection closed successfully.
2025-07-21 22:46:13,152 - INFO - app.core.security - [Redis] Connected to localhost (127.0.0.1):6380
2025-07-21 22:46:13,156 - INFO - app.core.security - [Redis] AOF persistence already enabled.
2025-07-21 22:47:14,999 - INFO - app.core.security - [Redis] Connection closed successfully.
2025-07-21 22:47:40,395 - INFO - app.core.security - [Redis] Connected to localhost (127.0.0.1):6380
2025-07-21 22:47:40,398 - INFO - app.core.security - [Redis] AOF persistence already enabled.
2025-07-21 22:48:05,652 - INFO - app.core.security - [Redis] Connection closed successfully.
2025-07-21 22:48:08,194 - INFO - app.core.security - [Redis] Connected to localhost (127.0.0.1):6380
2025-07-21 22:48:08,198 - INFO - app.core.security - [Redis] AOF persistence already enabled.
2025-07-21 22:48:39,076 - INFO - app.core.security - [Redis] Connection closed successfully.
