2025-07-23 23:21:56,381 - INFO - app.core.security - [Redis] Connected to localhost (127.0.0.1):6380
2025-07-23 23:21:56,383 - INFO - app.core.security - [Redis] AOF persistence already enabled.
2025-07-23 23:22:32,589 - INFO - app.core.security - [Redis] Connection closed successfully.
2025-07-23 23:34:33,679 - INFO - app.core.security - [Redis] Connected to localhost (127.0.0.1):6380
2025-07-23 23:34:33,681 - INFO - app.core.security - [Redis] AOF persistence already enabled.
2025-07-23 23:35:17,185 - INFO - app.core.security - [Redis] Connection closed successfully.
2025-07-23 23:35:19,400 - INFO - app.core.security - [Redis] Connected to localhost (127.0.0.1):6380
2025-07-23 23:35:19,401 - INFO - app.core.security - [Redis] AOF persistence already enabled.
2025-07-23 23:36:01,164 - INFO - app.core.security - [Redis] Connection closed successfully.
2025-07-23 23:36:18,577 - INFO - app.core.security - [Redis] Connected to localhost (127.0.0.1):6380
2025-07-23 23:36:18,579 - INFO - app.core.security - [Redis] AOF persistence already enabled.
2025-07-23 23:37:38,528 - INFO - app.core.security - [Redis] Connection closed successfully.
2025-07-23 23:37:40,796 - INFO - app.core.security - [Redis] Connected to localhost (127.0.0.1):6380
2025-07-23 23:37:40,797 - INFO - app.core.security - [Redis] AOF persistence already enabled.
2025-07-23 23:39:44,024 - INFO - app.core.security - [Redis] Connection closed successfully.
2025-07-23 23:44:26,416 - INFO - app.core.security - [Redis] Connected to localhost (127.0.0.1):6380
2025-07-23 23:44:26,418 - INFO - app.core.security - [Redis] AOF persistence already enabled.
2025-07-23 23:44:45,083 - INFO - app.core.security - [Redis] Connection closed successfully.
2025-07-23 23:48:19,568 - INFO - app.core.security - [Redis] Connected to localhost (127.0.0.1):6380
2025-07-23 23:48:19,571 - INFO - app.core.security - [Redis] AOF persistence already enabled.
2025-07-23 23:48:44,428 - INFO - app.core.security - [Redis] Connection closed successfully.
2025-07-24 01:45:13,139 - INFO - app.core.security - [Redis] Connected to localhost (127.0.0.1):6380
2025-07-24 01:45:13,852 - INFO - app.core.security - [Redis] AOF persistence already enabled.
2025-07-24 01:46:22,285 - ERROR - app.core.security - Authentication error in get_user_from_service_or_user_token: Could not validate credentials
Traceback (most recent call last):
  File "C:\Users\Dhanush\FASTAPI\app\core\security.py", line 94, in decode_token
    payload = jwt.decode(token, settings.SECRET_KEY, algorithms=[settings.ALGORITHM])
  File "C:\Users\Dhanush\FASTAPI\venv\Lib\site-packages\jose\jwt.py", line 174, in decode
    _validate_claims(
    ~~~~~~~~~~~~~~~~^
        claims,
        ^^^^^^^
    ...<5 lines>...
        options=defaults,
        ^^^^^^^^^^^^^^^^^
    )
    ^
  File "C:\Users\Dhanush\FASTAPI\venv\Lib\site-packages\jose\jwt.py", line 497, in _validate_claims
    _validate_exp(claims, leeway=leeway)
    ~~~~~~~~~~~~~^^^^^^^^^^^^^^^^^^^^^^^
  File "C:\Users\Dhanush\FASTAPI\venv\Lib\site-packages\jose\jwt.py", line 331, in _validate_exp
    raise ExpiredSignatureError("Signature has expired.")
jose.exceptions.ExpiredSignatureError: Signature has expired.

During handling of the above exception, another exception occurred:

Traceback (most recent call last):
  File "C:\Users\Dhanush\FASTAPI\app\core\security.py", line 377, in get_user_from_service_or_user_token
    payload = decode_token(token)
  File "C:\Users\Dhanush\FASTAPI\app\core\security.py", line 99, in decode_token
    raise JWTError("Could not validate credentials")
jose.exceptions.JWTError: Could not validate credentials
2025-07-24 01:46:22,340 - ERROR - app.core.security - Authentication error in get_user_from_service_or_user_token: Could not validate credentials
Traceback (most recent call last):
  File "C:\Users\Dhanush\FASTAPI\app\core\security.py", line 94, in decode_token
    payload = jwt.decode(token, settings.SECRET_KEY, algorithms=[settings.ALGORITHM])
  File "C:\Users\Dhanush\FASTAPI\venv\Lib\site-packages\jose\jwt.py", line 174, in decode
    _validate_claims(
    ~~~~~~~~~~~~~~~~^
        claims,
        ^^^^^^^
    ...<5 lines>...
        options=defaults,
        ^^^^^^^^^^^^^^^^^
    )
    ^
  File "C:\Users\Dhanush\FASTAPI\venv\Lib\site-packages\jose\jwt.py", line 497, in _validate_claims
    _validate_exp(claims, leeway=leeway)
    ~~~~~~~~~~~~~^^^^^^^^^^^^^^^^^^^^^^^
  File "C:\Users\Dhanush\FASTAPI\venv\Lib\site-packages\jose\jwt.py", line 331, in _validate_exp
    raise ExpiredSignatureError("Signature has expired.")
jose.exceptions.ExpiredSignatureError: Signature has expired.

During handling of the above exception, another exception occurred:

Traceback (most recent call last):
  File "C:\Users\Dhanush\FASTAPI\app\core\security.py", line 377, in get_user_from_service_or_user_token
    payload = decode_token(token)
  File "C:\Users\Dhanush\FASTAPI\app\core\security.py", line 99, in decode_token
    raise JWTError("Could not validate credentials")
jose.exceptions.JWTError: Could not validate credentials
2025-07-24 01:46:29,951 - INFO - app.core.security - LOGOUT: user_id=30, email=dhanush777ss@gmail.com, user_type=live, time=2025-07-24T08:46:29.951182
2025-07-24 01:54:51,288 - INFO - app.core.security - [Redis] Connection closed successfully.
2025-07-24 01:55:45,932 - INFO - app.core.security - [Redis] Connected to localhost (127.0.0.1):6380
2025-07-24 01:55:45,935 - INFO - app.core.security - [Redis] AOF persistence already enabled.
2025-07-24 01:56:51,602 - INFO - app.core.security - [Redis] Connection closed successfully.
2025-07-24 02:06:41,340 - INFO - app.core.security - [Redis] Connected to localhost (127.0.0.1):6380
2025-07-24 02:06:41,344 - INFO - app.core.security - [Redis] AOF persistence already enabled.
2025-07-24 02:08:15,241 - INFO - app.core.security - [Redis] Connection closed successfully.
2025-07-24 02:20:01,683 - INFO - app.core.security - [Redis] Connected to localhost (127.0.0.1):6380
2025-07-24 02:20:01,687 - INFO - app.core.security - [Redis] AOF persistence already enabled.
2025-07-24 02:21:54,923 - INFO - app.core.security - [Redis] Connection closed successfully.
2025-07-24 04:01:22,749 - INFO - app.core.security - [Redis] Connected to localhost (127.0.0.1):6380
2025-07-24 04:01:22,764 - INFO - app.core.security - [Redis] AOF persistence already enabled.
2025-07-24 04:05:12,655 - INFO - app.core.security - [Redis] Connection closed successfully.
2025-07-24 04:10:30,490 - INFO - app.core.security - [Redis] Connected to localhost (127.0.0.1):6380
2025-07-24 04:10:30,491 - INFO - app.core.security - [Redis] AOF persistence already enabled.
2025-07-24 04:12:30,754 - INFO - app.core.security - LOGIN: user_id=9, email=kodideladinesh123@gmail.com, user_type=live, time=2025-07-24T11:12:30.753955
2025-07-24 04:13:13,373 - INFO - app.core.security - [Redis] Connection closed successfully.
2025-07-24 04:14:48,402 - INFO - app.core.security - [Redis] Connected to localhost (127.0.0.1):6380
2025-07-24 04:14:48,403 - INFO - app.core.security - [Redis] AOF persistence already enabled.
2025-07-24 04:15:09,743 - INFO - app.core.security - [Redis] Connection closed successfully.
2025-07-24 04:15:15,496 - INFO - app.core.security - [Redis] Connected to localhost (127.0.0.1):6380
2025-07-24 04:15:15,499 - INFO - app.core.security - [Redis] AOF persistence already enabled.
2025-07-24 04:16:14,568 - INFO - app.core.security - [Redis] Connection closed successfully.
2025-07-24 04:27:24,875 - INFO - app.core.security - [Redis] Connected to localhost (127.0.0.1):6380
2025-07-24 04:27:24,877 - INFO - app.core.security - [Redis] AOF persistence already enabled.
2025-07-24 04:27:39,921 - INFO - app.core.security - LOGOUT: user_id=9, email=kodideladinesh123@gmail.com, user_type=live, time=2025-07-24T11:27:39.921144
2025-07-24 04:27:45,904 - INFO - app.core.security - LOGIN: user_id=31, email=dhanush777ss@gmail.com, user_type=live, time=2025-07-24T11:27:45.904583
2025-07-24 04:32:39,731 - INFO - app.core.security - [Redis] Connection closed successfully.
2025-07-24 04:36:46,312 - INFO - app.core.security - [Redis] Connected to localhost (127.0.0.1):6380
2025-07-24 04:36:46,316 - INFO - app.core.security - [Redis] AOF persistence already enabled.
2025-07-24 04:38:09,266 - INFO - app.core.security - [Redis] Connection closed successfully.
2025-07-24 04:38:30,177 - INFO - app.core.security - [Redis] Connected to localhost (127.0.0.1):6380
2025-07-24 04:38:30,178 - INFO - app.core.security - [Redis] AOF persistence already enabled.
2025-07-24 04:39:16,620 - INFO - app.core.security - LOGOUT: user_id=31, email=dhanush777ss@gmail.com, user_type=live, time=2025-07-24T11:39:16.620798
2025-07-24 04:39:38,056 - INFO - app.core.security - LOGIN: user_id=9, email=kodideladinesh123@gmail.com, user_type=live, time=2025-07-24T11:39:38.055981
2025-07-24 04:41:44,276 - INFO - app.core.security - [Redis] Connection closed successfully.
2025-07-24 04:41:46,567 - INFO - app.core.security - [Redis] Connected to localhost (127.0.0.1):6380
2025-07-24 04:41:46,568 - INFO - app.core.security - [Redis] AOF persistence already enabled.
2025-07-24 04:41:48,900 - INFO - app.core.security - [Redis] Connection closed successfully.
2025-07-24 04:45:52,909 - INFO - app.core.security - [Redis] Connected to localhost (127.0.0.1):6380
2025-07-24 04:45:52,912 - INFO - app.core.security - [Redis] AOF persistence already enabled.
2025-07-24 04:47:23,432 - INFO - app.core.security - [Redis] Connection closed successfully.
2025-07-24 05:38:51,185 - INFO - app.core.security - [Redis] Connected to localhost (127.0.0.1):6380
2025-07-24 05:38:51,187 - INFO - app.core.security - [Redis] AOF persistence already enabled.
2025-07-24 05:41:57,516 - INFO - app.core.security - [Redis] Connection closed successfully.
2025-07-24 05:43:52,907 - INFO - app.core.security - [Redis] Connected to localhost (127.0.0.1):6380
2025-07-24 05:43:52,910 - INFO - app.core.security - [Redis] AOF persistence already enabled.
2025-07-24 05:46:11,811 - INFO - app.core.security - [Redis] Connection closed successfully.
2025-07-24 05:48:25,004 - INFO - app.core.security - [Redis] Connected to localhost (127.0.0.1):6380
2025-07-24 05:48:25,006 - INFO - app.core.security - [Redis] AOF persistence already enabled.
2025-07-24 05:49:54,096 - INFO - app.core.security - [Redis] Connection closed successfully.
2025-07-24 05:51:27,801 - INFO - app.core.security - [Redis] Connected to localhost (127.0.0.1):6380
2025-07-24 05:51:27,802 - INFO - app.core.security - [Redis] AOF persistence already enabled.
2025-07-24 05:52:43,137 - INFO - app.core.security - [Redis] Connection closed successfully.
2025-07-24 21:40:59,021 - ERROR - app.core.security - [Redis] Connection failed: Error Multiple exceptions: [Errno 10061] Connect call failed ('::1', 6380, 0, 0), [Errno 10061] Connect call failed ('127.0.0.1', 6380) connecting to localhost:6380.
Traceback (most recent call last):
  File "C:\Users\Dhanush\FASTAPI\venv\Lib\site-packages\redis\asyncio\connection.py", line 302, in connect_check_health
    await self.retry.call_with_retry(
        lambda: self._connect(), lambda error: self.disconnect()
    )
  File "C:\Users\Dhanush\FASTAPI\venv\Lib\site-packages\redis\asyncio\retry.py", line 71, in call_with_retry
    return await do()
           ^^^^^^^^^^
  File "C:\Users\Dhanush\FASTAPI\venv\Lib\site-packages\redis\asyncio\connection.py", line 755, in _connect
    reader, writer = await asyncio.open_connection(
                     ^^^^^^^^^^^^^^^^^^^^^^^^^^^^^^
        **self._connection_arguments()
        ^^^^^^^^^^^^^^^^^^^^^^^^^^^^^^
    )
    ^
  File "C:\Users\Dhanush\AppData\Local\Programs\Python\Python313\Lib\asyncio\streams.py", line 48, in open_connection
    transport, _ = await loop.create_connection(
                   ^^^^^^^^^^^^^^^^^^^^^^^^^^^^^
        lambda: protocol, host, port, **kwds)
        ^^^^^^^^^^^^^^^^^^^^^^^^^^^^^^^^^^^^^
  File "C:\Users\Dhanush\AppData\Local\Programs\Python\Python313\Lib\asyncio\base_events.py", line 1174, in create_connection
    raise OSError('Multiple exceptions: {}'.format(
        ', '.join(str(exc) for exc in exceptions)))
OSError: Multiple exceptions: [Errno 10061] Connect call failed ('::1', 6380, 0, 0), [Errno 10061] Connect call failed ('127.0.0.1', 6380)

During handling of the above exception, another exception occurred:

Traceback (most recent call last):
  File "C:\Users\Dhanush\FASTAPI\app\core\security.py", line 139, in connect_to_redis
    await client.ping()
  File "C:\Users\Dhanush\FASTAPI\venv\Lib\site-packages\redis\asyncio\client.py", line 672, in execute_command
    conn = self.connection or await pool.get_connection()
                              ^^^^^^^^^^^^^^^^^^^^^^^^^^^
  File "C:\Users\Dhanush\FASTAPI\venv\Lib\site-packages\redis\asyncio\connection.py", line 1141, in get_connection
    await self.ensure_connection(connection)
  File "C:\Users\Dhanush\FASTAPI\venv\Lib\site-packages\redis\asyncio\connection.py", line 1174, in ensure_connection
    await connection.connect()
  File "C:\Users\Dhanush\FASTAPI\venv\Lib\site-packages\redis\asyncio\connection.py", line 296, in connect
    await self.connect_check_health(check_health=True)
  File "C:\Users\Dhanush\FASTAPI\venv\Lib\site-packages\redis\asyncio\connection.py", line 310, in connect_check_health
    raise ConnectionError(self._error_message(e))
redis.exceptions.ConnectionError: Error Multiple exceptions: [Errno 10061] Connect call failed ('::1', 6380, 0, 0), [Errno 10061] Connect call failed ('127.0.0.1', 6380) connecting to localhost:6380.
2025-07-24 21:41:47,984 - ERROR - app.core.security - Authentication error in get_user_from_service_or_user_token: Could not validate credentials
Traceback (most recent call last):
  File "C:\Users\Dhanush\FASTAPI\app\core\security.py", line 94, in decode_token
    payload = jwt.decode(token, settings.SECRET_KEY, algorithms=[settings.ALGORITHM])
  File "C:\Users\Dhanush\FASTAPI\venv\Lib\site-packages\jose\jwt.py", line 174, in decode
    _validate_claims(
    ~~~~~~~~~~~~~~~~^
        claims,
        ^^^^^^^
    ...<5 lines>...
        options=defaults,
        ^^^^^^^^^^^^^^^^^
    )
    ^
  File "C:\Users\Dhanush\FASTAPI\venv\Lib\site-packages\jose\jwt.py", line 497, in _validate_claims
    _validate_exp(claims, leeway=leeway)
    ~~~~~~~~~~~~~^^^^^^^^^^^^^^^^^^^^^^^
  File "C:\Users\Dhanush\FASTAPI\venv\Lib\site-packages\jose\jwt.py", line 331, in _validate_exp
    raise ExpiredSignatureError("Signature has expired.")
jose.exceptions.ExpiredSignatureError: Signature has expired.

During handling of the above exception, another exception occurred:

Traceback (most recent call last):
  File "C:\Users\Dhanush\FASTAPI\app\core\security.py", line 377, in get_user_from_service_or_user_token
    payload = decode_token(token)
  File "C:\Users\Dhanush\FASTAPI\app\core\security.py", line 99, in decode_token
    raise JWTError("Could not validate credentials")
jose.exceptions.JWTError: Could not validate credentials
2025-07-24 21:41:48,031 - ERROR - app.core.security - Authentication error in get_user_from_service_or_user_token: Could not validate credentials
Traceback (most recent call last):
  File "C:\Users\Dhanush\FASTAPI\app\core\security.py", line 94, in decode_token
    payload = jwt.decode(token, settings.SECRET_KEY, algorithms=[settings.ALGORITHM])
  File "C:\Users\Dhanush\FASTAPI\venv\Lib\site-packages\jose\jwt.py", line 174, in decode
    _validate_claims(
    ~~~~~~~~~~~~~~~~^
        claims,
        ^^^^^^^
    ...<5 lines>...
        options=defaults,
        ^^^^^^^^^^^^^^^^^
    )
    ^
  File "C:\Users\Dhanush\FASTAPI\venv\Lib\site-packages\jose\jwt.py", line 497, in _validate_claims
    _validate_exp(claims, leeway=leeway)
    ~~~~~~~~~~~~~^^^^^^^^^^^^^^^^^^^^^^^
  File "C:\Users\Dhanush\FASTAPI\venv\Lib\site-packages\jose\jwt.py", line 331, in _validate_exp
    raise ExpiredSignatureError("Signature has expired.")
jose.exceptions.ExpiredSignatureError: Signature has expired.

During handling of the above exception, another exception occurred:

Traceback (most recent call last):
  File "C:\Users\Dhanush\FASTAPI\app\core\security.py", line 377, in get_user_from_service_or_user_token
    payload = decode_token(token)
  File "C:\Users\Dhanush\FASTAPI\app\core\security.py", line 99, in decode_token
    raise JWTError("Could not validate credentials")
jose.exceptions.JWTError: Could not validate credentials
2025-07-24 21:41:51,938 - ERROR - app.core.security - [Redis] Connection failed: Error Multiple exceptions: [Errno 10061] Connect call failed ('::1', 6380, 0, 0), [Errno 10061] Connect call failed ('127.0.0.1', 6380) connecting to localhost:6380.
Traceback (most recent call last):
  File "C:\Users\Dhanush\FASTAPI\venv\Lib\site-packages\redis\asyncio\connection.py", line 302, in connect_check_health
    await self.retry.call_with_retry(
        lambda: self._connect(), lambda error: self.disconnect()
    )
  File "C:\Users\Dhanush\FASTAPI\venv\Lib\site-packages\redis\asyncio\retry.py", line 71, in call_with_retry
    return await do()
           ^^^^^^^^^^
  File "C:\Users\Dhanush\FASTAPI\venv\Lib\site-packages\redis\asyncio\connection.py", line 755, in _connect
    reader, writer = await asyncio.open_connection(
                     ^^^^^^^^^^^^^^^^^^^^^^^^^^^^^^
        **self._connection_arguments()
        ^^^^^^^^^^^^^^^^^^^^^^^^^^^^^^
    )
    ^
  File "C:\Users\Dhanush\AppData\Local\Programs\Python\Python313\Lib\asyncio\streams.py", line 48, in open_connection
    transport, _ = await loop.create_connection(
                   ^^^^^^^^^^^^^^^^^^^^^^^^^^^^^
        lambda: protocol, host, port, **kwds)
        ^^^^^^^^^^^^^^^^^^^^^^^^^^^^^^^^^^^^^
  File "C:\Users\Dhanush\AppData\Local\Programs\Python\Python313\Lib\asyncio\base_events.py", line 1174, in create_connection
    raise OSError('Multiple exceptions: {}'.format(
        ', '.join(str(exc) for exc in exceptions)))
OSError: Multiple exceptions: [Errno 10061] Connect call failed ('::1', 6380, 0, 0), [Errno 10061] Connect call failed ('127.0.0.1', 6380)

During handling of the above exception, another exception occurred:

Traceback (most recent call last):
  File "C:\Users\Dhanush\FASTAPI\app\core\security.py", line 139, in connect_to_redis
    await client.ping()
  File "C:\Users\Dhanush\FASTAPI\venv\Lib\site-packages\redis\asyncio\client.py", line 672, in execute_command
    conn = self.connection or await pool.get_connection()
                              ^^^^^^^^^^^^^^^^^^^^^^^^^^^
  File "C:\Users\Dhanush\FASTAPI\venv\Lib\site-packages\redis\asyncio\connection.py", line 1141, in get_connection
    await self.ensure_connection(connection)
  File "C:\Users\Dhanush\FASTAPI\venv\Lib\site-packages\redis\asyncio\connection.py", line 1174, in ensure_connection
    await connection.connect()
  File "C:\Users\Dhanush\FASTAPI\venv\Lib\site-packages\redis\asyncio\connection.py", line 296, in connect
    await self.connect_check_health(check_health=True)
  File "C:\Users\Dhanush\FASTAPI\venv\Lib\site-packages\redis\asyncio\connection.py", line 310, in connect_check_health
    raise ConnectionError(self._error_message(e))
redis.exceptions.ConnectionError: Error Multiple exceptions: [Errno 10061] Connect call failed ('::1', 6380, 0, 0), [Errno 10061] Connect call failed ('127.0.0.1', 6380) connecting to localhost:6380.
2025-07-24 21:41:52,092 - ERROR - app.core.security - [Redis] Connection failed: Error Multiple exceptions: [Errno 10061] Connect call failed ('::1', 6380, 0, 0), [Errno 10061] Connect call failed ('127.0.0.1', 6380) connecting to localhost:6380.
Traceback (most recent call last):
  File "C:\Users\Dhanush\FASTAPI\venv\Lib\site-packages\redis\asyncio\connection.py", line 302, in connect_check_health
    await self.retry.call_with_retry(
        lambda: self._connect(), lambda error: self.disconnect()
    )
  File "C:\Users\Dhanush\FASTAPI\venv\Lib\site-packages\redis\asyncio\retry.py", line 71, in call_with_retry
    return await do()
           ^^^^^^^^^^
  File "C:\Users\Dhanush\FASTAPI\venv\Lib\site-packages\redis\asyncio\connection.py", line 755, in _connect
    reader, writer = await asyncio.open_connection(
                     ^^^^^^^^^^^^^^^^^^^^^^^^^^^^^^
        **self._connection_arguments()
        ^^^^^^^^^^^^^^^^^^^^^^^^^^^^^^
    )
    ^
  File "C:\Users\Dhanush\AppData\Local\Programs\Python\Python313\Lib\asyncio\streams.py", line 48, in open_connection
    transport, _ = await loop.create_connection(
                   ^^^^^^^^^^^^^^^^^^^^^^^^^^^^^
        lambda: protocol, host, port, **kwds)
        ^^^^^^^^^^^^^^^^^^^^^^^^^^^^^^^^^^^^^
  File "C:\Users\Dhanush\AppData\Local\Programs\Python\Python313\Lib\asyncio\base_events.py", line 1174, in create_connection
    raise OSError('Multiple exceptions: {}'.format(
        ', '.join(str(exc) for exc in exceptions)))
OSError: Multiple exceptions: [Errno 10061] Connect call failed ('::1', 6380, 0, 0), [Errno 10061] Connect call failed ('127.0.0.1', 6380)

During handling of the above exception, another exception occurred:

Traceback (most recent call last):
  File "C:\Users\Dhanush\FASTAPI\app\core\security.py", line 139, in connect_to_redis
    await client.ping()
  File "C:\Users\Dhanush\FASTAPI\venv\Lib\site-packages\redis\asyncio\client.py", line 672, in execute_command
    conn = self.connection or await pool.get_connection()
                              ^^^^^^^^^^^^^^^^^^^^^^^^^^^
  File "C:\Users\Dhanush\FASTAPI\venv\Lib\site-packages\redis\asyncio\connection.py", line 1141, in get_connection
    await self.ensure_connection(connection)
  File "C:\Users\Dhanush\FASTAPI\venv\Lib\site-packages\redis\asyncio\connection.py", line 1174, in ensure_connection
    await connection.connect()
  File "C:\Users\Dhanush\FASTAPI\venv\Lib\site-packages\redis\asyncio\connection.py", line 296, in connect
    await self.connect_check_health(check_health=True)
  File "C:\Users\Dhanush\FASTAPI\venv\Lib\site-packages\redis\asyncio\connection.py", line 310, in connect_check_health
    raise ConnectionError(self._error_message(e))
redis.exceptions.ConnectionError: Error Multiple exceptions: [Errno 10061] Connect call failed ('::1', 6380, 0, 0), [Errno 10061] Connect call failed ('127.0.0.1', 6380) connecting to localhost:6380.
2025-07-24 21:41:52,114 - ERROR - app.core.security - [Redis] Connection failed: Error Multiple exceptions: [Errno 10061] Connect call failed ('::1', 6380, 0, 0), [Errno 10061] Connect call failed ('127.0.0.1', 6380) connecting to localhost:6380.
Traceback (most recent call last):
  File "C:\Users\Dhanush\FASTAPI\venv\Lib\site-packages\redis\asyncio\connection.py", line 302, in connect_check_health
    await self.retry.call_with_retry(
        lambda: self._connect(), lambda error: self.disconnect()
    )
  File "C:\Users\Dhanush\FASTAPI\venv\Lib\site-packages\redis\asyncio\retry.py", line 71, in call_with_retry
    return await do()
           ^^^^^^^^^^
  File "C:\Users\Dhanush\FASTAPI\venv\Lib\site-packages\redis\asyncio\connection.py", line 755, in _connect
    reader, writer = await asyncio.open_connection(
                     ^^^^^^^^^^^^^^^^^^^^^^^^^^^^^^
        **self._connection_arguments()
        ^^^^^^^^^^^^^^^^^^^^^^^^^^^^^^
    )
    ^
  File "C:\Users\Dhanush\AppData\Local\Programs\Python\Python313\Lib\asyncio\streams.py", line 48, in open_connection
    transport, _ = await loop.create_connection(
                   ^^^^^^^^^^^^^^^^^^^^^^^^^^^^^
        lambda: protocol, host, port, **kwds)
        ^^^^^^^^^^^^^^^^^^^^^^^^^^^^^^^^^^^^^
  File "C:\Users\Dhanush\AppData\Local\Programs\Python\Python313\Lib\asyncio\base_events.py", line 1174, in create_connection
    raise OSError('Multiple exceptions: {}'.format(
        ', '.join(str(exc) for exc in exceptions)))
OSError: Multiple exceptions: [Errno 10061] Connect call failed ('::1', 6380, 0, 0), [Errno 10061] Connect call failed ('127.0.0.1', 6380)

During handling of the above exception, another exception occurred:

Traceback (most recent call last):
  File "C:\Users\Dhanush\FASTAPI\app\core\security.py", line 139, in connect_to_redis
    await client.ping()
  File "C:\Users\Dhanush\FASTAPI\venv\Lib\site-packages\redis\asyncio\client.py", line 672, in execute_command
    conn = self.connection or await pool.get_connection()
                              ^^^^^^^^^^^^^^^^^^^^^^^^^^^
  File "C:\Users\Dhanush\FASTAPI\venv\Lib\site-packages\redis\asyncio\connection.py", line 1141, in get_connection
    await self.ensure_connection(connection)
  File "C:\Users\Dhanush\FASTAPI\venv\Lib\site-packages\redis\asyncio\connection.py", line 1174, in ensure_connection
    await connection.connect()
  File "C:\Users\Dhanush\FASTAPI\venv\Lib\site-packages\redis\asyncio\connection.py", line 296, in connect
    await self.connect_check_health(check_health=True)
  File "C:\Users\Dhanush\FASTAPI\venv\Lib\site-packages\redis\asyncio\connection.py", line 310, in connect_check_health
    raise ConnectionError(self._error_message(e))
redis.exceptions.ConnectionError: Error Multiple exceptions: [Errno 10061] Connect call failed ('::1', 6380, 0, 0), [Errno 10061] Connect call failed ('127.0.0.1', 6380) connecting to localhost:6380.
2025-07-24 21:41:52,126 - ERROR - app.core.security - [Redis] Connection failed: Error Multiple exceptions: [Errno 10061] Connect call failed ('::1', 6380, 0, 0), [Errno 10061] Connect call failed ('127.0.0.1', 6380) connecting to localhost:6380.
Traceback (most recent call last):
  File "C:\Users\Dhanush\FASTAPI\venv\Lib\site-packages\redis\asyncio\connection.py", line 302, in connect_check_health
    await self.retry.call_with_retry(
        lambda: self._connect(), lambda error: self.disconnect()
    )
  File "C:\Users\Dhanush\FASTAPI\venv\Lib\site-packages\redis\asyncio\retry.py", line 71, in call_with_retry
    return await do()
           ^^^^^^^^^^
  File "C:\Users\Dhanush\FASTAPI\venv\Lib\site-packages\redis\asyncio\connection.py", line 755, in _connect
    reader, writer = await asyncio.open_connection(
                     ^^^^^^^^^^^^^^^^^^^^^^^^^^^^^^
        **self._connection_arguments()
        ^^^^^^^^^^^^^^^^^^^^^^^^^^^^^^
    )
    ^
  File "C:\Users\Dhanush\AppData\Local\Programs\Python\Python313\Lib\asyncio\streams.py", line 48, in open_connection
    transport, _ = await loop.create_connection(
                   ^^^^^^^^^^^^^^^^^^^^^^^^^^^^^
        lambda: protocol, host, port, **kwds)
        ^^^^^^^^^^^^^^^^^^^^^^^^^^^^^^^^^^^^^
  File "C:\Users\Dhanush\AppData\Local\Programs\Python\Python313\Lib\asyncio\base_events.py", line 1174, in create_connection
    raise OSError('Multiple exceptions: {}'.format(
        ', '.join(str(exc) for exc in exceptions)))
OSError: Multiple exceptions: [Errno 10061] Connect call failed ('::1', 6380, 0, 0), [Errno 10061] Connect call failed ('127.0.0.1', 6380)

During handling of the above exception, another exception occurred:

Traceback (most recent call last):
  File "C:\Users\Dhanush\FASTAPI\app\core\security.py", line 139, in connect_to_redis
    await client.ping()
  File "C:\Users\Dhanush\FASTAPI\venv\Lib\site-packages\redis\asyncio\client.py", line 672, in execute_command
    conn = self.connection or await pool.get_connection()
                              ^^^^^^^^^^^^^^^^^^^^^^^^^^^
  File "C:\Users\Dhanush\FASTAPI\venv\Lib\site-packages\redis\asyncio\connection.py", line 1141, in get_connection
    await self.ensure_connection(connection)
  File "C:\Users\Dhanush\FASTAPI\venv\Lib\site-packages\redis\asyncio\connection.py", line 1174, in ensure_connection
    await connection.connect()
  File "C:\Users\Dhanush\FASTAPI\venv\Lib\site-packages\redis\asyncio\connection.py", line 296, in connect
    await self.connect_check_health(check_health=True)
  File "C:\Users\Dhanush\FASTAPI\venv\Lib\site-packages\redis\asyncio\connection.py", line 310, in connect_check_health
    raise ConnectionError(self._error_message(e))
redis.exceptions.ConnectionError: Error Multiple exceptions: [Errno 10061] Connect call failed ('::1', 6380, 0, 0), [Errno 10061] Connect call failed ('127.0.0.1', 6380) connecting to localhost:6380.
2025-07-25 02:13:11,001 - INFO - app.core.security - [Redis] Connected to localhost (127.0.0.1):6380
2025-07-25 02:13:11,004 - INFO - app.core.security - [Redis] AOF persistence already enabled.
2025-07-25 02:13:46,227 - INFO - app.core.security - LOGOUT: user_id=31, email=cocexej852@dariolo.com, user_type=live, time=2025-07-25T09:13:46.227419
2025-07-25 02:13:49,089 - INFO - app.core.security - LOGIN: user_id=4, email=dhanush777ss@gmail.com, user_type=live, time=2025-07-25T09:13:49.089197
2025-07-25 02:14:50,094 - INFO - app.core.security - [Redis] Connection closed successfully.
2025-07-25 02:19:11,738 - INFO - app.core.security - [Redis] Connected to localhost (127.0.0.1):6380
2025-07-25 02:19:11,740 - INFO - app.core.security - [Redis] AOF persistence already enabled.
2025-07-25 02:20:36,945 - INFO - app.core.security - [Redis] Connection closed successfully.
2025-07-25 02:22:49,323 - INFO - app.core.security - [Redis] Connected to localhost (127.0.0.1):6380
2025-07-25 02:22:49,327 - INFO - app.core.security - [Redis] AOF persistence already enabled.
2025-07-25 02:24:29,185 - INFO - app.core.security - [Redis] Connection closed successfully.
2025-07-25 02:26:26,149 - INFO - app.core.security - [Redis] Connected to localhost (127.0.0.1):6380
2025-07-25 02:26:26,152 - INFO - app.core.security - [Redis] AOF persistence already enabled.
2025-07-25 02:28:53,287 - INFO - app.core.security - [Redis] Connection closed successfully.
2025-07-25 02:29:52,578 - INFO - app.core.security - [Redis] Connected to localhost (127.0.0.1):6380
2025-07-25 02:29:52,580 - INFO - app.core.security - [Redis] AOF persistence already enabled.
2025-07-25 02:30:52,716 - INFO - app.core.security - [Redis] Connection closed successfully.
2025-07-25 02:32:09,949 - INFO - app.core.security - [Redis] Connected to localhost (127.0.0.1):6380
2025-07-25 02:32:09,951 - INFO - app.core.security - [Redis] AOF persistence already enabled.
2025-07-25 02:32:39,879 - INFO - app.core.security - [Redis] Connection closed successfully.
2025-07-25 02:34:54,619 - INFO - app.core.security - [Redis] Connected to localhost (127.0.0.1):6380
2025-07-25 02:34:54,621 - INFO - app.core.security - [Redis] AOF persistence already enabled.
2025-07-25 02:35:12,978 - INFO - app.core.security - LOGIN: user_id=31, email=dhanush777ss@gmail.com, user_type=live, time=2025-07-25T09:35:12.977932
2025-07-25 02:35:31,829 - INFO - app.core.security - [Redis] Connection closed successfully.
2025-07-25 02:37:12,822 - INFO - app.core.security - [Redis] Connected to localhost (127.0.0.1):6380
2025-07-25 02:37:12,825 - INFO - app.core.security - [Redis] AOF persistence already enabled.
2025-07-25 02:37:56,627 - INFO - app.core.security - LOGOUT: user_id=31, email=dhanush777ss@gmail.com, user_type=live, time=2025-07-25T09:37:56.627422
2025-07-25 02:37:59,582 - INFO - app.core.security - LOGIN: user_id=1, email=dhanush777ss@gmail.com, user_type=demo, time=2025-07-25T09:37:59.582267
2025-07-25 02:39:06,525 - INFO - app.core.security - [Redis] Connection closed successfully.
