2025-07-18 04:47:25,890 - INFO - app.core.security - [Redis] Connected to localhost (127.0.0.1):6380
2025-07-18 04:47:25,892 - INFO - app.core.security - [Redis] AOF persistence already enabled.
2025-07-18 04:49:05,838 - INFO - app.core.security - [Redis] Connection closed successfully.
2025-07-18 04:52:01,646 - INFO - app.core.security - [Redis] Connected to localhost (127.0.0.1):6380
2025-07-18 04:52:01,648 - INFO - app.core.security - [Redis] AOF persistence already enabled.
2025-07-18 04:52:20,335 - INFO - app.core.security - LOGOUT: user_id=1, email=dhanush777ss@gmail.com, user_type=demo, time=2025-07-18T11:52:20.335677
2025-07-18 04:52:22,821 - INFO - app.core.security - LOGIN: user_id=4, email=dhanush777ss@gmail.com, user_type=live, time=2025-07-18T11:52:22.821053
2025-07-18 04:54:13,563 - INFO - app.core.security - [Redis] Connection closed successfully.
2025-07-18 05:07:18,213 - INFO - app.core.security - [Redis] Connected to localhost (127.0.0.1):6380
2025-07-18 05:07:18,215 - INFO - app.core.security - [Redis] AOF persistence already enabled.
2025-07-18 05:08:01,322 - INFO - app.core.security - [Redis] Connection closed successfully.
2025-07-18 05:10:25,120 - INFO - app.core.security - [Redis] Connected to localhost (127.0.0.1):6380
2025-07-18 05:10:25,122 - INFO - app.core.security - [Redis] AOF persistence already enabled.
2025-07-18 05:11:10,155 - INFO - app.core.security - [Redis] Connection closed successfully.
2025-07-20 20:56:11,083 - ERROR - app.core.security - [Redis] Connection failed: Error Multiple exceptions: [Errno 10061] Connect call failed ('::1', 6380, 0, 0), [Errno 10061] Connect call failed ('127.0.0.1', 6380) connecting to localhost:6380.
Traceback (most recent call last):
  File "C:\Users\Dhanush\FASTAPI\venv\Lib\site-packages\redis\asyncio\connection.py", line 302, in connect_check_health
    await self.retry.call_with_retry(
        lambda: self._connect(), lambda error: self.disconnect()
    )
  File "C:\Users\Dhanush\FASTAPI\venv\Lib\site-packages\redis\asyncio\retry.py", line 71, in call_with_retry
    return await do()
           ^^^^^^^^^^
  File "C:\Users\Dhanush\FASTAPI\venv\Lib\site-packages\redis\asyncio\connection.py", line 755, in _connect
    reader, writer = await asyncio.open_connection(
                     ^^^^^^^^^^^^^^^^^^^^^^^^^^^^^^
        **self._connection_arguments()
        ^^^^^^^^^^^^^^^^^^^^^^^^^^^^^^
    )
    ^
  File "C:\Users\Dhanush\AppData\Local\Programs\Python\Python313\Lib\asyncio\streams.py", line 48, in open_connection
    transport, _ = await loop.create_connection(
                   ^^^^^^^^^^^^^^^^^^^^^^^^^^^^^
        lambda: protocol, host, port, **kwds)
        ^^^^^^^^^^^^^^^^^^^^^^^^^^^^^^^^^^^^^
  File "C:\Users\Dhanush\AppData\Local\Programs\Python\Python313\Lib\asyncio\base_events.py", line 1174, in create_connection
    raise OSError('Multiple exceptions: {}'.format(
        ', '.join(str(exc) for exc in exceptions)))
OSError: Multiple exceptions: [Errno 10061] Connect call failed ('::1', 6380, 0, 0), [Errno 10061] Connect call failed ('127.0.0.1', 6380)

During handling of the above exception, another exception occurred:

Traceback (most recent call last):
  File "C:\Users\Dhanush\FASTAPI\app\core\security.py", line 206, in connect_to_redis
    await client.ping()
  File "C:\Users\Dhanush\FASTAPI\venv\Lib\site-packages\redis\asyncio\client.py", line 672, in execute_command
    conn = self.connection or await pool.get_connection()
                              ^^^^^^^^^^^^^^^^^^^^^^^^^^^
  File "C:\Users\Dhanush\FASTAPI\venv\Lib\site-packages\redis\asyncio\connection.py", line 1141, in get_connection
    await self.ensure_connection(connection)
  File "C:\Users\Dhanush\FASTAPI\venv\Lib\site-packages\redis\asyncio\connection.py", line 1174, in ensure_connection
    await connection.connect()
  File "C:\Users\Dhanush\FASTAPI\venv\Lib\site-packages\redis\asyncio\connection.py", line 296, in connect
    await self.connect_check_health(check_health=True)
  File "C:\Users\Dhanush\FASTAPI\venv\Lib\site-packages\redis\asyncio\connection.py", line 310, in connect_check_health
    raise ConnectionError(self._error_message(e))
redis.exceptions.ConnectionError: Error Multiple exceptions: [Errno 10061] Connect call failed ('::1', 6380, 0, 0), [Errno 10061] Connect call failed ('127.0.0.1', 6380) connecting to localhost:6380.
