2025-07-30 21:32:52,081 - INFO - service_provider - SERVICE PROVIDER ORDER FOUND: order_id=1428-001, status=PROCESSING, user_id=31
2025-07-30 21:32:52,082 - INFO - service_provider - SERVICE PROVIDER STATUS TRANSITION: PROCESSING -> OPEN
2025-07-30 21:32:52,168 - ERROR - service_provider - SERVICE PROVIDER EXCEPTION: Error in service_provider_order_execution: type object 'datetime.datetime' has no attribute 'datetime'
Traceback (most recent call last):
  File "C:\Users\Dhanush\FASTAPI\app\api\v1\endpoints\orders.py", line 261, in update_user_static_orders
    if isinstance(created_at, datetime.datetime):
                              ^^^^^^^^^^^^^^^^^
AttributeError: type object 'datetime.datetime' has no attribute 'datetime'

During handling of the above exception, another exception occurred:

Traceback (most recent call last):
  File "C:\Users\Dhanush\FASTAPI\app\api\v1\endpoints\orders.py", line 4057, in service_provider_order_execution
    updated_order = await _handle_order_open_transition(
                    ^^^^^^^^^^^^^^^^^^^^^^^^^^^^^^^^^^^^
    ...<6 lines>...
    )
    ^
  File "C:\Users\Dhanush\FASTAPI\app\api\v1\endpoints\orders.py", line 3971, in _handle_order_open_transition
    await update_user_static_orders(updated_order_db.order_user_id, db, redis_client, 'live')
  File "C:\Users\Dhanush\FASTAPI\app\api\v1\endpoints\orders.py", line 330, in update_user_static_orders
    return {"open_orders": [], "pending_orders": [], "updated_at": datetime.datetime.now().isoformat()}
                                                                   ^^^^^^^^^^^^^^^^^
AttributeError: type object 'datetime.datetime' has no attribute 'datetime'
2025-07-30 21:38:28,679 - INFO - service_provider - SERVICE PROVIDER ORDER FOUND: order_id=1428-001, status=OPEN, user_id=31
2025-07-30 21:38:28,681 - INFO - service_provider - SERVICE PROVIDER STATUS TRANSITION: OPEN -> OPEN
2025-07-30 21:38:28,681 - ERROR - service_provider - SERVICE PROVIDER ERROR: Invalid status transition from OPEN to OPEN
2025-07-30 21:38:28,683 - ERROR - service_provider - SERVICE PROVIDER EXCEPTION: Error in service_provider_order_execution: 400: Invalid status transition from OPEN to OPEN
Traceback (most recent call last):
  File "C:\Users\Dhanush\FASTAPI\app\api\v1\endpoints\orders.py", line 4074, in service_provider_order_execution
    raise HTTPException(status_code=400, detail=error_msg)
fastapi.exceptions.HTTPException: 400: Invalid status transition from OPEN to OPEN
