2025-07-23 23:21:59,467 - INFO - websocket - Redis publisher task started. Publishing to channel 'market_data_updates'.
2025-07-23 23:22:00,371 - INFO - websocket - WebSocket connection attempt from 127.0.0.1:54050
2025-07-23 23:22:00,372 - INFO - websocket - WebSocket connection accepted from 127.0.0.1:54050
2025-07-23 23:22:00,374 - INFO - websocket - WebSocket auth: Authenticating user 5B0HV (live)
2025-07-23 23:22:00,579 - WARNING - websocket - Authentication failed for account_number 5B0HV (type live): User not found in correct table.
2025-07-23 23:22:06,897 - INFO - websocket - WebSocket connection attempt from 127.0.0.1:54084
2025-07-23 23:22:06,899 - INFO - websocket - WebSocket connection accepted from 127.0.0.1:54084
2025-07-23 23:22:06,903 - INFO - websocket - WebSocket auth: Authenticating user 5B0HV (live)
2025-07-23 23:22:07,011 - WARNING - websocket - Authentication failed for account_number 5B0HV (type live): User not found in correct table.
2025-07-23 23:22:12,843 - INFO - websocket - WebSocket connection attempt from 127.0.0.1:54096
2025-07-23 23:22:12,844 - INFO - websocket - WebSocket connection accepted from 127.0.0.1:54096
2025-07-23 23:22:12,846 - INFO - websocket - WebSocket auth: Authenticating user 5B0HV (live)
2025-07-23 23:22:12,919 - WARNING - websocket - Authentication failed for account_number 5B0HV (type live): User not found in correct table.
2025-07-23 23:22:18,862 - INFO - websocket - WebSocket connection attempt from 127.0.0.1:54107
2025-07-23 23:22:18,863 - INFO - websocket - WebSocket connection accepted from 127.0.0.1:54107
2025-07-23 23:22:18,865 - INFO - websocket - WebSocket auth: Authenticating user 5B0HV (live)
2025-07-23 23:22:18,954 - WARNING - websocket - Authentication failed for account_number 5B0HV (type live): User not found in correct table.
2025-07-23 23:22:24,845 - INFO - websocket - WebSocket connection attempt from 127.0.0.1:54115
2025-07-23 23:22:24,847 - INFO - websocket - WebSocket connection accepted from 127.0.0.1:54115
2025-07-23 23:22:24,851 - INFO - websocket - WebSocket auth: Authenticating user 5B0HV (live)
2025-07-23 23:22:24,937 - WARNING - websocket - Authentication failed for account_number 5B0HV (type live): User not found in correct table.
2025-07-23 23:22:30,845 - INFO - websocket - WebSocket connection attempt from 127.0.0.1:54127
2025-07-23 23:22:30,846 - INFO - websocket - WebSocket connection accepted from 127.0.0.1:54127
2025-07-23 23:22:30,848 - INFO - websocket - WebSocket auth: Authenticating user 5B0HV (live)
2025-07-23 23:22:30,923 - WARNING - websocket - Authentication failed for account_number 5B0HV (type live): User not found in correct table.
2025-07-23 23:22:31,773 - INFO - websocket - Redis publisher task cancelled.
2025-07-23 23:22:31,773 - INFO - websocket - Redis publisher task finished.
2025-07-23 23:34:36,899 - INFO - websocket - Redis publisher task started. Publishing to channel 'market_data_updates'.
2025-07-23 23:34:40,846 - INFO - websocket - WebSocket connection attempt from 127.0.0.1:55282
2025-07-23 23:34:40,846 - INFO - websocket - WebSocket connection accepted from 127.0.0.1:55282
2025-07-23 23:34:40,848 - INFO - websocket - WebSocket auth: Authenticating user 5B0HV (live)
2025-07-23 23:34:41,201 - WARNING - websocket - Authentication failed for account_number 5B0HV (type live): User not found in correct table.
2025-07-23 23:34:46,839 - INFO - websocket - WebSocket connection attempt from 127.0.0.1:55298
2025-07-23 23:34:46,839 - INFO - websocket - WebSocket connection accepted from 127.0.0.1:55298
2025-07-23 23:34:46,842 - INFO - websocket - WebSocket auth: Authenticating user 5B0HV (live)
2025-07-23 23:34:46,909 - WARNING - websocket - Authentication failed for account_number 5B0HV (type live): User not found in correct table.
2025-07-23 23:34:52,843 - INFO - websocket - WebSocket connection attempt from 127.0.0.1:55309
2025-07-23 23:34:52,844 - INFO - websocket - WebSocket connection accepted from 127.0.0.1:55309
2025-07-23 23:34:52,847 - INFO - websocket - WebSocket auth: Authenticating user 5B0HV (live)
2025-07-23 23:34:52,912 - WARNING - websocket - Authentication failed for account_number 5B0HV (type live): User not found in correct table.
2025-07-23 23:34:58,846 - INFO - websocket - WebSocket connection attempt from 127.0.0.1:55327
2025-07-23 23:34:58,848 - INFO - websocket - WebSocket connection accepted from 127.0.0.1:55327
2025-07-23 23:34:58,851 - INFO - websocket - WebSocket auth: Authenticating user 5B0HV (live)
2025-07-23 23:34:58,924 - WARNING - websocket - Authentication failed for account_number 5B0HV (type live): User not found in correct table.
2025-07-23 23:35:04,846 - INFO - websocket - WebSocket connection attempt from 127.0.0.1:55341
2025-07-23 23:35:04,847 - INFO - websocket - WebSocket connection accepted from 127.0.0.1:55341
2025-07-23 23:35:04,850 - INFO - websocket - WebSocket auth: Authenticating user 5B0HV (live)
2025-07-23 23:35:04,927 - WARNING - websocket - Authentication failed for account_number 5B0HV (type live): User not found in correct table.
2025-07-23 23:35:10,839 - INFO - websocket - WebSocket connection attempt from 127.0.0.1:55353
2025-07-23 23:35:10,840 - INFO - websocket - WebSocket connection accepted from 127.0.0.1:55353
2025-07-23 23:35:10,842 - INFO - websocket - WebSocket auth: Authenticating user 5B0HV (live)
2025-07-23 23:35:10,905 - WARNING - websocket - Authentication failed for account_number 5B0HV (type live): User not found in correct table.
2025-07-23 23:35:17,111 - INFO - websocket - Redis publisher task cancelled.
2025-07-23 23:35:17,111 - INFO - websocket - Redis publisher task finished.
2025-07-23 23:35:21,975 - INFO - websocket - Redis publisher task started. Publishing to channel 'market_data_updates'.
2025-07-23 23:35:22,643 - INFO - websocket - WebSocket connection attempt from 127.0.0.1:55361
2025-07-23 23:35:22,644 - INFO - websocket - WebSocket connection accepted from 127.0.0.1:55361
2025-07-23 23:35:22,646 - INFO - websocket - WebSocket auth: Authenticating user 5B0HV (live)
2025-07-23 23:35:22,747 - ERROR - websocket - Unexpected WS auth error for 127.0.0.1:55361: (pymysql.err.OperationalError) (1226, "User 'u436589492_testingserver' has exceeded the 'max_user_connections' resource (current value: 50)")
(Background on this error at: https://sqlalche.me/e/20/e3q8)
Traceback (most recent call last):
  File "C:\Users\Dhanush\FASTAPI\venv\Lib\site-packages\sqlalchemy\engine\base.py", line 145, in __init__
    self._dbapi_connection = engine.raw_connection()
                             ~~~~~~~~~~~~~~~~~~~~~^^
  File "C:\Users\Dhanush\FASTAPI\venv\Lib\site-packages\sqlalchemy\engine\base.py", line 3297, in raw_connection
    return self.pool.connect()
           ~~~~~~~~~~~~~~~~~^^
  File "C:\Users\Dhanush\FASTAPI\venv\Lib\site-packages\sqlalchemy\pool\base.py", line 449, in connect
    return _ConnectionFairy._checkout(self)
           ~~~~~~~~~~~~~~~~~~~~~~~~~~^^^^^^
  File "C:\Users\Dhanush\FASTAPI\venv\Lib\site-packages\sqlalchemy\pool\base.py", line 1264, in _checkout
    fairy = _ConnectionRecord.checkout(pool)
  File "C:\Users\Dhanush\FASTAPI\venv\Lib\site-packages\sqlalchemy\pool\base.py", line 713, in checkout
    rec = pool._do_get()
  File "C:\Users\Dhanush\FASTAPI\venv\Lib\site-packages\sqlalchemy\pool\impl.py", line 179, in _do_get
    with util.safe_reraise():
         ~~~~~~~~~~~~~~~~~^^
  File "C:\Users\Dhanush\FASTAPI\venv\Lib\site-packages\sqlalchemy\util\langhelpers.py", line 224, in __exit__
    raise exc_value.with_traceback(exc_tb)
  File "C:\Users\Dhanush\FASTAPI\venv\Lib\site-packages\sqlalchemy\pool\impl.py", line 177, in _do_get
    return self._create_connection()
           ~~~~~~~~~~~~~~~~~~~~~~~^^
  File "C:\Users\Dhanush\FASTAPI\venv\Lib\site-packages\sqlalchemy\pool\base.py", line 390, in _create_connection
    return _ConnectionRecord(self)
  File "C:\Users\Dhanush\FASTAPI\venv\Lib\site-packages\sqlalchemy\pool\base.py", line 675, in __init__
    self.__connect()
    ~~~~~~~~~~~~~~^^
  File "C:\Users\Dhanush\FASTAPI\venv\Lib\site-packages\sqlalchemy\pool\base.py", line 901, in __connect
    with util.safe_reraise():
         ~~~~~~~~~~~~~~~~~^^
  File "C:\Users\Dhanush\FASTAPI\venv\Lib\site-packages\sqlalchemy\util\langhelpers.py", line 224, in __exit__
    raise exc_value.with_traceback(exc_tb)
  File "C:\Users\Dhanush\FASTAPI\venv\Lib\site-packages\sqlalchemy\pool\base.py", line 897, in __connect
    self.dbapi_connection = connection = pool._invoke_creator(self)
                                         ~~~~~~~~~~~~~~~~~~~~^^^^^^
  File "C:\Users\Dhanush\FASTAPI\venv\Lib\site-packages\sqlalchemy\engine\create.py", line 646, in connect
    return dialect.connect(*cargs, **cparams)
           ~~~~~~~~~~~~~~~^^^^^^^^^^^^^^^^^^^
  File "C:\Users\Dhanush\FASTAPI\venv\Lib\site-packages\sqlalchemy\engine\default.py", line 625, in connect
    return self.loaded_dbapi.connect(*cargs, **cparams)  # type: ignore[no-any-return]  # NOQA: E501
           ~~~~~~~~~~~~~~~~~~~~~~~~~^^^^^^^^^^^^^^^^^^^
  File "C:\Users\Dhanush\FASTAPI\venv\Lib\site-packages\sqlalchemy\dialects\mysql\aiomysql.py", line 270, in connect
    await_only(creator_fn(*arg, **kw)),
    ~~~~~~~~~~^^^^^^^^^^^^^^^^^^^^^^^^
  File "C:\Users\Dhanush\FASTAPI\venv\Lib\site-packages\sqlalchemy\util\_concurrency_py3k.py", line 132, in await_only
    return current.parent.switch(awaitable)  # type: ignore[no-any-return,attr-defined] # noqa: E501
           ~~~~~~~~~~~~~~~~~~~~~^^^^^^^^^^^
  File "C:\Users\Dhanush\FASTAPI\venv\Lib\site-packages\sqlalchemy\util\_concurrency_py3k.py", line 196, in greenlet_spawn
    value = await result
            ^^^^^^^^^^^^
  File "C:\Users\Dhanush\FASTAPI\venv\Lib\site-packages\aiomysql\connection.py", line 75, in _connect
    await conn._connect()
  File "C:\Users\Dhanush\FASTAPI\venv\Lib\site-packages\aiomysql\connection.py", line 540, in _connect
    await self._request_authentication()
  File "C:\Users\Dhanush\FASTAPI\venv\Lib\site-packages\aiomysql\connection.py", line 844, in _request_authentication
    auth_packet = await self._read_packet()
                  ^^^^^^^^^^^^^^^^^^^^^^^^^
  File "C:\Users\Dhanush\FASTAPI\venv\Lib\site-packages\aiomysql\connection.py", line 652, in _read_packet
    packet.raise_for_error()
    ~~~~~~~~~~~~~~~~~~~~~~^^
  File "C:\Users\Dhanush\FASTAPI\venv\Lib\site-packages\pymysql\protocol.py", line 219, in raise_for_error
    err.raise_mysql_exception(self._data)
    ~~~~~~~~~~~~~~~~~~~~~~~~~^^^^^^^^^^^^
  File "C:\Users\Dhanush\FASTAPI\venv\Lib\site-packages\pymysql\err.py", line 150, in raise_mysql_exception
    raise errorclass(errno, errval)
pymysql.err.OperationalError: (1226, "User 'u436589492_testingserver' has exceeded the 'max_user_connections' resource (current value: 50)")

The above exception was the direct cause of the following exception:

Traceback (most recent call last):
  File "C:\Users\Dhanush\FASTAPI\app\api\v1\endpoints\market_data_ws.py", line 930, in websocket_endpoint
    db_user_instance = await get_user_by_account_number(db, account_number, user_type)
                       ^^^^^^^^^^^^^^^^^^^^^^^^^^^^^^^^^^^^^^^^^^^^^^^^^^^^^^^^^^^^^^^
  File "C:\Users\Dhanush\FASTAPI\app\crud\user.py", line 39, in get_user_by_account_number
    result = await db.execute(
             ^^^^^^^^^^^^^^^^^
        select(User).filter(User.account_number == account_number, User.user_type == user_type)
        ^^^^^^^^^^^^^^^^^^^^^^^^^^^^^^^^^^^^^^^^^^^^^^^^^^^^^^^^^^^^^^^^^^^^^^^^^^^^^^^^^^^^^^^
    )
    ^
  File "C:\Users\Dhanush\FASTAPI\venv\Lib\site-packages\sqlalchemy\ext\asyncio\session.py", line 463, in execute
    result = await greenlet_spawn(
             ^^^^^^^^^^^^^^^^^^^^^
    ...<6 lines>...
    )
    ^
  File "C:\Users\Dhanush\FASTAPI\venv\Lib\site-packages\sqlalchemy\util\_concurrency_py3k.py", line 201, in greenlet_spawn
    result = context.throw(*sys.exc_info())
  File "C:\Users\Dhanush\FASTAPI\venv\Lib\site-packages\sqlalchemy\orm\session.py", line 2365, in execute
    return self._execute_internal(
           ~~~~~~~~~~~~~~~~~~~~~~^
        statement,
        ^^^^^^^^^^
    ...<4 lines>...
        _add_event=_add_event,
        ^^^^^^^^^^^^^^^^^^^^^^
    )
    ^
  File "C:\Users\Dhanush\FASTAPI\venv\Lib\site-packages\sqlalchemy\orm\session.py", line 2241, in _execute_internal
    conn = self._connection_for_bind(bind)
  File "C:\Users\Dhanush\FASTAPI\venv\Lib\site-packages\sqlalchemy\orm\session.py", line 2110, in _connection_for_bind
    return trans._connection_for_bind(engine, execution_options)
           ~~~~~~~~~~~~~~~~~~~~~~~~~~^^^^^^^^^^^^^^^^^^^^^^^^^^^
  File "<string>", line 2, in _connection_for_bind
  File "C:\Users\Dhanush\FASTAPI\venv\Lib\site-packages\sqlalchemy\orm\state_changes.py", line 139, in _go
    ret_value = fn(self, *arg, **kw)
  File "C:\Users\Dhanush\FASTAPI\venv\Lib\site-packages\sqlalchemy\orm\session.py", line 1189, in _connection_for_bind
    conn = bind.connect()
  File "C:\Users\Dhanush\FASTAPI\venv\Lib\site-packages\sqlalchemy\engine\base.py", line 3273, in connect
    return self._connection_cls(self)
           ~~~~~~~~~~~~~~~~~~~~^^^^^^
  File "C:\Users\Dhanush\FASTAPI\venv\Lib\site-packages\sqlalchemy\engine\base.py", line 147, in __init__
    Connection._handle_dbapi_exception_noconnection(
    ~~~~~~~~~~~~~~~~~~~~~~~~~~~~~~~~~~~~~~~~~~~~~~~^
        err, dialect, engine
        ^^^^^^^^^^^^^^^^^^^^
    )
    ^
  File "C:\Users\Dhanush\FASTAPI\venv\Lib\site-packages\sqlalchemy\engine\base.py", line 2436, in _handle_dbapi_exception_noconnection
    raise sqlalchemy_exception.with_traceback(exc_info[2]) from e
  File "C:\Users\Dhanush\FASTAPI\venv\Lib\site-packages\sqlalchemy\engine\base.py", line 145, in __init__
    self._dbapi_connection = engine.raw_connection()
                             ~~~~~~~~~~~~~~~~~~~~~^^
  File "C:\Users\Dhanush\FASTAPI\venv\Lib\site-packages\sqlalchemy\engine\base.py", line 3297, in raw_connection
    return self.pool.connect()
           ~~~~~~~~~~~~~~~~~^^
  File "C:\Users\Dhanush\FASTAPI\venv\Lib\site-packages\sqlalchemy\pool\base.py", line 449, in connect
    return _ConnectionFairy._checkout(self)
           ~~~~~~~~~~~~~~~~~~~~~~~~~~^^^^^^
  File "C:\Users\Dhanush\FASTAPI\venv\Lib\site-packages\sqlalchemy\pool\base.py", line 1264, in _checkout
    fairy = _ConnectionRecord.checkout(pool)
  File "C:\Users\Dhanush\FASTAPI\venv\Lib\site-packages\sqlalchemy\pool\base.py", line 713, in checkout
    rec = pool._do_get()
  File "C:\Users\Dhanush\FASTAPI\venv\Lib\site-packages\sqlalchemy\pool\impl.py", line 179, in _do_get
    with util.safe_reraise():
         ~~~~~~~~~~~~~~~~~^^
  File "C:\Users\Dhanush\FASTAPI\venv\Lib\site-packages\sqlalchemy\util\langhelpers.py", line 224, in __exit__
    raise exc_value.with_traceback(exc_tb)
  File "C:\Users\Dhanush\FASTAPI\venv\Lib\site-packages\sqlalchemy\pool\impl.py", line 177, in _do_get
    return self._create_connection()
           ~~~~~~~~~~~~~~~~~~~~~~~^^
  File "C:\Users\Dhanush\FASTAPI\venv\Lib\site-packages\sqlalchemy\pool\base.py", line 390, in _create_connection
    return _ConnectionRecord(self)
  File "C:\Users\Dhanush\FASTAPI\venv\Lib\site-packages\sqlalchemy\pool\base.py", line 675, in __init__
    self.__connect()
    ~~~~~~~~~~~~~~^^
  File "C:\Users\Dhanush\FASTAPI\venv\Lib\site-packages\sqlalchemy\pool\base.py", line 901, in __connect
    with util.safe_reraise():
         ~~~~~~~~~~~~~~~~~^^
  File "C:\Users\Dhanush\FASTAPI\venv\Lib\site-packages\sqlalchemy\util\langhelpers.py", line 224, in __exit__
    raise exc_value.with_traceback(exc_tb)
  File "C:\Users\Dhanush\FASTAPI\venv\Lib\site-packages\sqlalchemy\pool\base.py", line 897, in __connect
    self.dbapi_connection = connection = pool._invoke_creator(self)
                                         ~~~~~~~~~~~~~~~~~~~~^^^^^^
  File "C:\Users\Dhanush\FASTAPI\venv\Lib\site-packages\sqlalchemy\engine\create.py", line 646, in connect
    return dialect.connect(*cargs, **cparams)
           ~~~~~~~~~~~~~~~^^^^^^^^^^^^^^^^^^^
  File "C:\Users\Dhanush\FASTAPI\venv\Lib\site-packages\sqlalchemy\engine\default.py", line 625, in connect
    return self.loaded_dbapi.connect(*cargs, **cparams)  # type: ignore[no-any-return]  # NOQA: E501
           ~~~~~~~~~~~~~~~~~~~~~~~~~^^^^^^^^^^^^^^^^^^^
  File "C:\Users\Dhanush\FASTAPI\venv\Lib\site-packages\sqlalchemy\dialects\mysql\aiomysql.py", line 270, in connect
    await_only(creator_fn(*arg, **kw)),
    ~~~~~~~~~~^^^^^^^^^^^^^^^^^^^^^^^^
  File "C:\Users\Dhanush\FASTAPI\venv\Lib\site-packages\sqlalchemy\util\_concurrency_py3k.py", line 132, in await_only
    return current.parent.switch(awaitable)  # type: ignore[no-any-return,attr-defined] # noqa: E501
           ~~~~~~~~~~~~~~~~~~~~~^^^^^^^^^^^
  File "C:\Users\Dhanush\FASTAPI\venv\Lib\site-packages\sqlalchemy\util\_concurrency_py3k.py", line 196, in greenlet_spawn
    value = await result
            ^^^^^^^^^^^^
  File "C:\Users\Dhanush\FASTAPI\venv\Lib\site-packages\aiomysql\connection.py", line 75, in _connect
    await conn._connect()
  File "C:\Users\Dhanush\FASTAPI\venv\Lib\site-packages\aiomysql\connection.py", line 540, in _connect
    await self._request_authentication()
  File "C:\Users\Dhanush\FASTAPI\venv\Lib\site-packages\aiomysql\connection.py", line 844, in _request_authentication
    auth_packet = await self._read_packet()
                  ^^^^^^^^^^^^^^^^^^^^^^^^^
  File "C:\Users\Dhanush\FASTAPI\venv\Lib\site-packages\aiomysql\connection.py", line 652, in _read_packet
    packet.raise_for_error()
    ~~~~~~~~~~~~~~~~~~~~~~^^
  File "C:\Users\Dhanush\FASTAPI\venv\Lib\site-packages\pymysql\protocol.py", line 219, in raise_for_error
    err.raise_mysql_exception(self._data)
    ~~~~~~~~~~~~~~~~~~~~~~~~~^^^^^^^^^^^^
  File "C:\Users\Dhanush\FASTAPI\venv\Lib\site-packages\pymysql\err.py", line 150, in raise_mysql_exception
    raise errorclass(errno, errval)
sqlalchemy.exc.OperationalError: (pymysql.err.OperationalError) (1226, "User 'u436589492_testingserver' has exceeded the 'max_user_connections' resource (current value: 50)")
(Background on this error at: https://sqlalche.me/e/20/e3q8)
2025-07-23 23:35:28,851 - INFO - websocket - WebSocket connection attempt from 127.0.0.1:55404
2025-07-23 23:35:28,852 - INFO - websocket - WebSocket connection accepted from 127.0.0.1:55404
2025-07-23 23:35:28,857 - INFO - websocket - WebSocket auth: Authenticating user 5B0HV (live)
2025-07-23 23:35:28,970 - WARNING - websocket - Authentication failed for account_number 5B0HV (type live): User not found in correct table.
2025-07-23 23:35:34,870 - INFO - websocket - WebSocket connection attempt from 127.0.0.1:55417
2025-07-23 23:35:34,877 - INFO - websocket - WebSocket connection accepted from 127.0.0.1:55417
2025-07-23 23:35:34,882 - INFO - websocket - WebSocket auth: Authenticating user 5B0HV (live)
2025-07-23 23:35:34,953 - WARNING - websocket - Authentication failed for account_number 5B0HV (type live): User not found in correct table.
2025-07-23 23:35:40,839 - INFO - websocket - WebSocket connection attempt from 127.0.0.1:55429
2025-07-23 23:35:40,840 - INFO - websocket - WebSocket connection accepted from 127.0.0.1:55429
2025-07-23 23:35:40,844 - INFO - websocket - WebSocket auth: Authenticating user 5B0HV (live)
2025-07-23 23:35:40,916 - WARNING - websocket - Authentication failed for account_number 5B0HV (type live): User not found in correct table.
2025-07-23 23:35:46,839 - INFO - websocket - WebSocket connection attempt from 127.0.0.1:55444
2025-07-23 23:35:46,839 - INFO - websocket - WebSocket connection accepted from 127.0.0.1:55444
2025-07-23 23:35:46,841 - INFO - websocket - WebSocket auth: Authenticating user 5B0HV (live)
2025-07-23 23:35:46,911 - WARNING - websocket - Authentication failed for account_number 5B0HV (type live): User not found in correct table.
2025-07-23 23:35:52,870 - INFO - websocket - WebSocket connection attempt from 127.0.0.1:55456
2025-07-23 23:35:52,872 - INFO - websocket - WebSocket connection accepted from 127.0.0.1:55456
2025-07-23 23:35:52,876 - INFO - websocket - WebSocket auth: Authenticating user 5B0HV (live)
2025-07-23 23:35:52,945 - WARNING - websocket - Authentication failed for account_number 5B0HV (type live): User not found in correct table.
2025-07-23 23:35:59,611 - INFO - websocket - WebSocket connection attempt from 127.0.0.1:55473
2025-07-23 23:35:59,708 - INFO - websocket - WebSocket connection accepted from 127.0.0.1:55473
2025-07-23 23:35:59,727 - INFO - websocket - WebSocket auth: Authenticating user 5B0HV (live)
2025-07-23 23:36:00,002 - WARNING - websocket - Authentication failed for account_number 5B0HV (type live): User not found in correct table.
2025-07-23 23:36:01,151 - INFO - websocket - Redis publisher task cancelled.
2025-07-23 23:36:01,151 - INFO - websocket - Redis publisher task finished.
2025-07-23 23:36:20,970 - INFO - websocket - Redis publisher task started. Publishing to channel 'market_data_updates'.
2025-07-23 23:36:23,864 - INFO - websocket - WebSocket connection attempt from 127.0.0.1:55532
2025-07-23 23:36:23,864 - INFO - websocket - WebSocket connection accepted from 127.0.0.1:55532
2025-07-23 23:36:23,867 - INFO - websocket - WebSocket auth: Authenticating user 5B0HV (live)
2025-07-23 23:36:23,950 - WARNING - websocket - Authentication failed for account_number 5B0HV (type live): User not found in correct table.
2025-07-23 23:36:30,145 - INFO - websocket - WebSocket connection attempt from 127.0.0.1:55547
2025-07-23 23:36:30,146 - INFO - websocket - WebSocket connection accepted from 127.0.0.1:55547
2025-07-23 23:36:30,155 - INFO - websocket - WebSocket auth: Authenticating user 5B0HV (live)
2025-07-23 23:36:30,253 - ERROR - websocket - Unexpected WS auth error for 127.0.0.1:55547: (pymysql.err.OperationalError) (1226, "User 'u436589492_testingserver' has exceeded the 'max_user_connections' resource (current value: 50)")
(Background on this error at: https://sqlalche.me/e/20/e3q8)
Traceback (most recent call last):
  File "C:\Users\Dhanush\FASTAPI\venv\Lib\site-packages\sqlalchemy\engine\base.py", line 145, in __init__
    self._dbapi_connection = engine.raw_connection()
                             ~~~~~~~~~~~~~~~~~~~~~^^
  File "C:\Users\Dhanush\FASTAPI\venv\Lib\site-packages\sqlalchemy\engine\base.py", line 3297, in raw_connection
    return self.pool.connect()
           ~~~~~~~~~~~~~~~~~^^
  File "C:\Users\Dhanush\FASTAPI\venv\Lib\site-packages\sqlalchemy\pool\base.py", line 449, in connect
    return _ConnectionFairy._checkout(self)
           ~~~~~~~~~~~~~~~~~~~~~~~~~~^^^^^^
  File "C:\Users\Dhanush\FASTAPI\venv\Lib\site-packages\sqlalchemy\pool\base.py", line 1264, in _checkout
    fairy = _ConnectionRecord.checkout(pool)
  File "C:\Users\Dhanush\FASTAPI\venv\Lib\site-packages\sqlalchemy\pool\base.py", line 713, in checkout
    rec = pool._do_get()
  File "C:\Users\Dhanush\FASTAPI\venv\Lib\site-packages\sqlalchemy\pool\impl.py", line 179, in _do_get
    with util.safe_reraise():
         ~~~~~~~~~~~~~~~~~^^
  File "C:\Users\Dhanush\FASTAPI\venv\Lib\site-packages\sqlalchemy\util\langhelpers.py", line 224, in __exit__
    raise exc_value.with_traceback(exc_tb)
  File "C:\Users\Dhanush\FASTAPI\venv\Lib\site-packages\sqlalchemy\pool\impl.py", line 177, in _do_get
    return self._create_connection()
           ~~~~~~~~~~~~~~~~~~~~~~~^^
  File "C:\Users\Dhanush\FASTAPI\venv\Lib\site-packages\sqlalchemy\pool\base.py", line 390, in _create_connection
    return _ConnectionRecord(self)
  File "C:\Users\Dhanush\FASTAPI\venv\Lib\site-packages\sqlalchemy\pool\base.py", line 675, in __init__
    self.__connect()
    ~~~~~~~~~~~~~~^^
  File "C:\Users\Dhanush\FASTAPI\venv\Lib\site-packages\sqlalchemy\pool\base.py", line 901, in __connect
    with util.safe_reraise():
         ~~~~~~~~~~~~~~~~~^^
  File "C:\Users\Dhanush\FASTAPI\venv\Lib\site-packages\sqlalchemy\util\langhelpers.py", line 224, in __exit__
    raise exc_value.with_traceback(exc_tb)
  File "C:\Users\Dhanush\FASTAPI\venv\Lib\site-packages\sqlalchemy\pool\base.py", line 897, in __connect
    self.dbapi_connection = connection = pool._invoke_creator(self)
                                         ~~~~~~~~~~~~~~~~~~~~^^^^^^
  File "C:\Users\Dhanush\FASTAPI\venv\Lib\site-packages\sqlalchemy\engine\create.py", line 646, in connect
    return dialect.connect(*cargs, **cparams)
           ~~~~~~~~~~~~~~~^^^^^^^^^^^^^^^^^^^
  File "C:\Users\Dhanush\FASTAPI\venv\Lib\site-packages\sqlalchemy\engine\default.py", line 625, in connect
    return self.loaded_dbapi.connect(*cargs, **cparams)  # type: ignore[no-any-return]  # NOQA: E501
           ~~~~~~~~~~~~~~~~~~~~~~~~~^^^^^^^^^^^^^^^^^^^
  File "C:\Users\Dhanush\FASTAPI\venv\Lib\site-packages\sqlalchemy\dialects\mysql\aiomysql.py", line 270, in connect
    await_only(creator_fn(*arg, **kw)),
    ~~~~~~~~~~^^^^^^^^^^^^^^^^^^^^^^^^
  File "C:\Users\Dhanush\FASTAPI\venv\Lib\site-packages\sqlalchemy\util\_concurrency_py3k.py", line 132, in await_only
    return current.parent.switch(awaitable)  # type: ignore[no-any-return,attr-defined] # noqa: E501
           ~~~~~~~~~~~~~~~~~~~~~^^^^^^^^^^^
  File "C:\Users\Dhanush\FASTAPI\venv\Lib\site-packages\sqlalchemy\util\_concurrency_py3k.py", line 196, in greenlet_spawn
    value = await result
            ^^^^^^^^^^^^
  File "C:\Users\Dhanush\FASTAPI\venv\Lib\site-packages\aiomysql\connection.py", line 75, in _connect
    await conn._connect()
  File "C:\Users\Dhanush\FASTAPI\venv\Lib\site-packages\aiomysql\connection.py", line 540, in _connect
    await self._request_authentication()
  File "C:\Users\Dhanush\FASTAPI\venv\Lib\site-packages\aiomysql\connection.py", line 844, in _request_authentication
    auth_packet = await self._read_packet()
                  ^^^^^^^^^^^^^^^^^^^^^^^^^
  File "C:\Users\Dhanush\FASTAPI\venv\Lib\site-packages\aiomysql\connection.py", line 652, in _read_packet
    packet.raise_for_error()
    ~~~~~~~~~~~~~~~~~~~~~~^^
  File "C:\Users\Dhanush\FASTAPI\venv\Lib\site-packages\pymysql\protocol.py", line 219, in raise_for_error
    err.raise_mysql_exception(self._data)
    ~~~~~~~~~~~~~~~~~~~~~~~~~^^^^^^^^^^^^
  File "C:\Users\Dhanush\FASTAPI\venv\Lib\site-packages\pymysql\err.py", line 150, in raise_mysql_exception
    raise errorclass(errno, errval)
pymysql.err.OperationalError: (1226, "User 'u436589492_testingserver' has exceeded the 'max_user_connections' resource (current value: 50)")

The above exception was the direct cause of the following exception:

Traceback (most recent call last):
  File "C:\Users\Dhanush\FASTAPI\app\api\v1\endpoints\market_data_ws.py", line 930, in websocket_endpoint
    db_user_instance = await get_user_by_account_number(db, account_number, user_type)
                       ^^^^^^^^^^^^^^^^^^^^^^^^^^^^^^^^^^^^^^^^^^^^^^^^^^^^^^^^^^^^^^^
  File "C:\Users\Dhanush\FASTAPI\app\crud\user.py", line 39, in get_user_by_account_number
    result = await db.execute(
             ^^^^^^^^^^^^^^^^^
        select(User).filter(User.account_number == account_number, User.user_type == user_type)
        ^^^^^^^^^^^^^^^^^^^^^^^^^^^^^^^^^^^^^^^^^^^^^^^^^^^^^^^^^^^^^^^^^^^^^^^^^^^^^^^^^^^^^^^
    )
    ^
  File "C:\Users\Dhanush\FASTAPI\venv\Lib\site-packages\sqlalchemy\ext\asyncio\session.py", line 463, in execute
    result = await greenlet_spawn(
             ^^^^^^^^^^^^^^^^^^^^^
    ...<6 lines>...
    )
    ^
  File "C:\Users\Dhanush\FASTAPI\venv\Lib\site-packages\sqlalchemy\util\_concurrency_py3k.py", line 201, in greenlet_spawn
    result = context.throw(*sys.exc_info())
  File "C:\Users\Dhanush\FASTAPI\venv\Lib\site-packages\sqlalchemy\orm\session.py", line 2365, in execute
    return self._execute_internal(
           ~~~~~~~~~~~~~~~~~~~~~~^
        statement,
        ^^^^^^^^^^
    ...<4 lines>...
        _add_event=_add_event,
        ^^^^^^^^^^^^^^^^^^^^^^
    )
    ^
  File "C:\Users\Dhanush\FASTAPI\venv\Lib\site-packages\sqlalchemy\orm\session.py", line 2241, in _execute_internal
    conn = self._connection_for_bind(bind)
  File "C:\Users\Dhanush\FASTAPI\venv\Lib\site-packages\sqlalchemy\orm\session.py", line 2110, in _connection_for_bind
    return trans._connection_for_bind(engine, execution_options)
           ~~~~~~~~~~~~~~~~~~~~~~~~~~^^^^^^^^^^^^^^^^^^^^^^^^^^^
  File "<string>", line 2, in _connection_for_bind
  File "C:\Users\Dhanush\FASTAPI\venv\Lib\site-packages\sqlalchemy\orm\state_changes.py", line 139, in _go
    ret_value = fn(self, *arg, **kw)
  File "C:\Users\Dhanush\FASTAPI\venv\Lib\site-packages\sqlalchemy\orm\session.py", line 1189, in _connection_for_bind
    conn = bind.connect()
  File "C:\Users\Dhanush\FASTAPI\venv\Lib\site-packages\sqlalchemy\engine\base.py", line 3273, in connect
    return self._connection_cls(self)
           ~~~~~~~~~~~~~~~~~~~~^^^^^^
  File "C:\Users\Dhanush\FASTAPI\venv\Lib\site-packages\sqlalchemy\engine\base.py", line 147, in __init__
    Connection._handle_dbapi_exception_noconnection(
    ~~~~~~~~~~~~~~~~~~~~~~~~~~~~~~~~~~~~~~~~~~~~~~~^
        err, dialect, engine
        ^^^^^^^^^^^^^^^^^^^^
    )
    ^
  File "C:\Users\Dhanush\FASTAPI\venv\Lib\site-packages\sqlalchemy\engine\base.py", line 2436, in _handle_dbapi_exception_noconnection
    raise sqlalchemy_exception.with_traceback(exc_info[2]) from e
  File "C:\Users\Dhanush\FASTAPI\venv\Lib\site-packages\sqlalchemy\engine\base.py", line 145, in __init__
    self._dbapi_connection = engine.raw_connection()
                             ~~~~~~~~~~~~~~~~~~~~~^^
  File "C:\Users\Dhanush\FASTAPI\venv\Lib\site-packages\sqlalchemy\engine\base.py", line 3297, in raw_connection
    return self.pool.connect()
           ~~~~~~~~~~~~~~~~~^^
  File "C:\Users\Dhanush\FASTAPI\venv\Lib\site-packages\sqlalchemy\pool\base.py", line 449, in connect
    return _ConnectionFairy._checkout(self)
           ~~~~~~~~~~~~~~~~~~~~~~~~~~^^^^^^
  File "C:\Users\Dhanush\FASTAPI\venv\Lib\site-packages\sqlalchemy\pool\base.py", line 1264, in _checkout
    fairy = _ConnectionRecord.checkout(pool)
  File "C:\Users\Dhanush\FASTAPI\venv\Lib\site-packages\sqlalchemy\pool\base.py", line 713, in checkout
    rec = pool._do_get()
  File "C:\Users\Dhanush\FASTAPI\venv\Lib\site-packages\sqlalchemy\pool\impl.py", line 179, in _do_get
    with util.safe_reraise():
         ~~~~~~~~~~~~~~~~~^^
  File "C:\Users\Dhanush\FASTAPI\venv\Lib\site-packages\sqlalchemy\util\langhelpers.py", line 224, in __exit__
    raise exc_value.with_traceback(exc_tb)
  File "C:\Users\Dhanush\FASTAPI\venv\Lib\site-packages\sqlalchemy\pool\impl.py", line 177, in _do_get
    return self._create_connection()
           ~~~~~~~~~~~~~~~~~~~~~~~^^
  File "C:\Users\Dhanush\FASTAPI\venv\Lib\site-packages\sqlalchemy\pool\base.py", line 390, in _create_connection
    return _ConnectionRecord(self)
  File "C:\Users\Dhanush\FASTAPI\venv\Lib\site-packages\sqlalchemy\pool\base.py", line 675, in __init__
    self.__connect()
    ~~~~~~~~~~~~~~^^
  File "C:\Users\Dhanush\FASTAPI\venv\Lib\site-packages\sqlalchemy\pool\base.py", line 901, in __connect
    with util.safe_reraise():
         ~~~~~~~~~~~~~~~~~^^
  File "C:\Users\Dhanush\FASTAPI\venv\Lib\site-packages\sqlalchemy\util\langhelpers.py", line 224, in __exit__
    raise exc_value.with_traceback(exc_tb)
  File "C:\Users\Dhanush\FASTAPI\venv\Lib\site-packages\sqlalchemy\pool\base.py", line 897, in __connect
    self.dbapi_connection = connection = pool._invoke_creator(self)
                                         ~~~~~~~~~~~~~~~~~~~~^^^^^^
  File "C:\Users\Dhanush\FASTAPI\venv\Lib\site-packages\sqlalchemy\engine\create.py", line 646, in connect
    return dialect.connect(*cargs, **cparams)
           ~~~~~~~~~~~~~~~^^^^^^^^^^^^^^^^^^^
  File "C:\Users\Dhanush\FASTAPI\venv\Lib\site-packages\sqlalchemy\engine\default.py", line 625, in connect
    return self.loaded_dbapi.connect(*cargs, **cparams)  # type: ignore[no-any-return]  # NOQA: E501
           ~~~~~~~~~~~~~~~~~~~~~~~~~^^^^^^^^^^^^^^^^^^^
  File "C:\Users\Dhanush\FASTAPI\venv\Lib\site-packages\sqlalchemy\dialects\mysql\aiomysql.py", line 270, in connect
    await_only(creator_fn(*arg, **kw)),
    ~~~~~~~~~~^^^^^^^^^^^^^^^^^^^^^^^^
  File "C:\Users\Dhanush\FASTAPI\venv\Lib\site-packages\sqlalchemy\util\_concurrency_py3k.py", line 132, in await_only
    return current.parent.switch(awaitable)  # type: ignore[no-any-return,attr-defined] # noqa: E501
           ~~~~~~~~~~~~~~~~~~~~~^^^^^^^^^^^
  File "C:\Users\Dhanush\FASTAPI\venv\Lib\site-packages\sqlalchemy\util\_concurrency_py3k.py", line 196, in greenlet_spawn
    value = await result
            ^^^^^^^^^^^^
  File "C:\Users\Dhanush\FASTAPI\venv\Lib\site-packages\aiomysql\connection.py", line 75, in _connect
    await conn._connect()
  File "C:\Users\Dhanush\FASTAPI\venv\Lib\site-packages\aiomysql\connection.py", line 540, in _connect
    await self._request_authentication()
  File "C:\Users\Dhanush\FASTAPI\venv\Lib\site-packages\aiomysql\connection.py", line 844, in _request_authentication
    auth_packet = await self._read_packet()
                  ^^^^^^^^^^^^^^^^^^^^^^^^^
  File "C:\Users\Dhanush\FASTAPI\venv\Lib\site-packages\aiomysql\connection.py", line 652, in _read_packet
    packet.raise_for_error()
    ~~~~~~~~~~~~~~~~~~~~~~^^
  File "C:\Users\Dhanush\FASTAPI\venv\Lib\site-packages\pymysql\protocol.py", line 219, in raise_for_error
    err.raise_mysql_exception(self._data)
    ~~~~~~~~~~~~~~~~~~~~~~~~~^^^^^^^^^^^^
  File "C:\Users\Dhanush\FASTAPI\venv\Lib\site-packages\pymysql\err.py", line 150, in raise_mysql_exception
    raise errorclass(errno, errval)
sqlalchemy.exc.OperationalError: (pymysql.err.OperationalError) (1226, "User 'u436589492_testingserver' has exceeded the 'max_user_connections' resource (current value: 50)")
(Background on this error at: https://sqlalche.me/e/20/e3q8)
2025-07-23 23:36:35,851 - INFO - websocket - WebSocket connection attempt from 127.0.0.1:55559
2025-07-23 23:36:35,861 - INFO - websocket - WebSocket connection accepted from 127.0.0.1:55559
2025-07-23 23:36:35,890 - INFO - websocket - WebSocket auth: Authenticating user 5B0HV (live)
2025-07-23 23:36:35,964 - WARNING - websocket - Authentication failed for account_number 5B0HV (type live): User not found in correct table.
2025-07-23 23:36:41,845 - INFO - websocket - WebSocket connection attempt from 127.0.0.1:55565
2025-07-23 23:36:41,846 - INFO - websocket - WebSocket connection accepted from 127.0.0.1:55565
2025-07-23 23:36:41,847 - INFO - websocket - WebSocket auth: Authenticating user 5B0HV (live)
2025-07-23 23:36:41,918 - WARNING - websocket - Authentication failed for account_number 5B0HV (type live): User not found in correct table.
2025-07-23 23:36:47,840 - INFO - websocket - WebSocket connection attempt from 127.0.0.1:55574
2025-07-23 23:36:47,840 - INFO - websocket - WebSocket connection accepted from 127.0.0.1:55574
2025-07-23 23:36:47,843 - INFO - websocket - WebSocket auth: Authenticating user 5B0HV (live)
2025-07-23 23:36:47,910 - WARNING - websocket - Authentication failed for account_number 5B0HV (type live): User not found in correct table.
2025-07-23 23:36:53,865 - INFO - websocket - WebSocket connection attempt from 127.0.0.1:55584
2025-07-23 23:36:53,866 - INFO - websocket - WebSocket connection accepted from 127.0.0.1:55584
2025-07-23 23:36:53,867 - INFO - websocket - WebSocket auth: Authenticating user 5B0HV (live)
2025-07-23 23:36:53,922 - WARNING - websocket - Authentication failed for account_number 5B0HV (type live): User not found in correct table.
2025-07-23 23:36:59,878 - INFO - websocket - WebSocket connection attempt from 127.0.0.1:55594
2025-07-23 23:36:59,879 - INFO - websocket - WebSocket connection accepted from 127.0.0.1:55594
2025-07-23 23:36:59,881 - INFO - websocket - WebSocket auth: Authenticating user 5B0HV (live)
2025-07-23 23:36:59,955 - WARNING - websocket - Authentication failed for account_number 5B0HV (type live): User not found in correct table.
2025-07-23 23:37:05,992 - INFO - websocket - WebSocket connection attempt from 127.0.0.1:55603
2025-07-23 23:37:05,992 - INFO - websocket - WebSocket connection accepted from 127.0.0.1:55603
2025-07-23 23:37:05,993 - INFO - websocket - WebSocket auth: Authenticating user 5B0HV (live)
2025-07-23 23:37:06,078 - WARNING - websocket - Authentication failed for account_number 5B0HV (type live): User not found in correct table.
2025-07-23 23:37:11,880 - INFO - websocket - WebSocket connection attempt from 127.0.0.1:55613
2025-07-23 23:37:11,881 - INFO - websocket - WebSocket connection accepted from 127.0.0.1:55613
2025-07-23 23:37:11,883 - INFO - websocket - WebSocket auth: Authenticating user 5B0HV (live)
2025-07-23 23:37:11,949 - WARNING - websocket - Authentication failed for account_number 5B0HV (type live): User not found in correct table.
2025-07-23 23:37:17,831 - INFO - websocket - WebSocket connection attempt from 127.0.0.1:55620
2025-07-23 23:37:17,831 - INFO - websocket - WebSocket connection accepted from 127.0.0.1:55620
2025-07-23 23:37:17,833 - INFO - websocket - WebSocket auth: Authenticating user 5B0HV (live)
2025-07-23 23:37:17,894 - WARNING - websocket - Authentication failed for account_number 5B0HV (type live): User not found in correct table.
2025-07-23 23:37:23,839 - INFO - websocket - WebSocket connection attempt from 127.0.0.1:55630
2025-07-23 23:37:23,839 - INFO - websocket - WebSocket connection accepted from 127.0.0.1:55630
2025-07-23 23:37:23,841 - INFO - websocket - WebSocket auth: Authenticating user 5B0HV (live)
2025-07-23 23:37:23,905 - WARNING - websocket - Authentication failed for account_number 5B0HV (type live): User not found in correct table.
2025-07-23 23:37:29,841 - INFO - websocket - WebSocket connection attempt from 127.0.0.1:55637
2025-07-23 23:37:29,842 - INFO - websocket - WebSocket connection accepted from 127.0.0.1:55637
2025-07-23 23:37:29,842 - INFO - websocket - WebSocket auth: Authenticating user 5B0HV (live)
2025-07-23 23:37:29,932 - WARNING - websocket - Authentication failed for account_number 5B0HV (type live): User not found in correct table.
2025-07-23 23:37:35,892 - INFO - websocket - WebSocket connection attempt from 127.0.0.1:55650
2025-07-23 23:37:35,893 - INFO - websocket - WebSocket connection accepted from 127.0.0.1:55650
2025-07-23 23:37:35,895 - INFO - websocket - WebSocket auth: Authenticating user 5B0HV (live)
2025-07-23 23:37:35,954 - WARNING - websocket - Authentication failed for account_number 5B0HV (type live): User not found in correct table.
2025-07-23 23:37:38,523 - INFO - websocket - Redis publisher task cancelled.
2025-07-23 23:37:38,523 - INFO - websocket - Redis publisher task finished.
2025-07-23 23:37:44,390 - INFO - websocket - Redis publisher task started. Publishing to channel 'market_data_updates'.
2025-07-23 23:37:45,094 - INFO - websocket - WebSocket connection attempt from 127.0.0.1:55665
2025-07-23 23:37:45,095 - INFO - websocket - WebSocket connection accepted from 127.0.0.1:55665
2025-07-23 23:37:45,097 - INFO - websocket - WebSocket auth: Authenticating user 5B0HV (live)
2025-07-23 23:37:45,405 - WARNING - websocket - Authentication failed for account_number 5B0HV (type live): User not found in correct table.
2025-07-23 23:37:50,845 - INFO - websocket - WebSocket connection attempt from 127.0.0.1:55702
2025-07-23 23:37:50,845 - INFO - websocket - WebSocket connection accepted from 127.0.0.1:55702
2025-07-23 23:37:50,847 - INFO - websocket - WebSocket auth: Authenticating user 5B0HV (live)
2025-07-23 23:37:50,916 - WARNING - websocket - Authentication failed for account_number 5B0HV (type live): User not found in correct table.
2025-07-23 23:37:56,846 - INFO - websocket - WebSocket connection attempt from 127.0.0.1:55714
2025-07-23 23:37:56,847 - INFO - websocket - WebSocket connection accepted from 127.0.0.1:55714
2025-07-23 23:37:56,850 - INFO - websocket - WebSocket auth: Authenticating user 5B0HV (live)
2025-07-23 23:37:56,924 - WARNING - websocket - Authentication failed for account_number 5B0HV (type live): User not found in correct table.
2025-07-23 23:38:02,852 - INFO - websocket - WebSocket connection attempt from 127.0.0.1:55731
2025-07-23 23:38:02,853 - INFO - websocket - WebSocket connection accepted from 127.0.0.1:55731
2025-07-23 23:38:02,855 - INFO - websocket - WebSocket auth: Authenticating user 5B0HV (live)
2025-07-23 23:38:02,929 - WARNING - websocket - Authentication failed for account_number 5B0HV (type live): User not found in correct table.
2025-07-23 23:38:09,102 - INFO - websocket - WebSocket connection attempt from 127.0.0.1:55741
2025-07-23 23:38:09,103 - INFO - websocket - WebSocket connection accepted from 127.0.0.1:55741
2025-07-23 23:38:09,109 - INFO - websocket - WebSocket auth: Authenticating user 5B0HV (live)
2025-07-23 23:38:09,197 - WARNING - websocket - Authentication failed for account_number 5B0HV (type live): User not found in correct table.
2025-07-23 23:38:14,857 - INFO - websocket - WebSocket connection attempt from 127.0.0.1:55750
2025-07-23 23:38:14,858 - INFO - websocket - WebSocket connection accepted from 127.0.0.1:55750
2025-07-23 23:38:14,860 - INFO - websocket - WebSocket auth: Authenticating user 5B0HV (live)
2025-07-23 23:38:14,930 - WARNING - websocket - Authentication failed for account_number 5B0HV (type live): User not found in correct table.
2025-07-23 23:38:20,859 - INFO - websocket - WebSocket connection attempt from 127.0.0.1:55758
2025-07-23 23:38:20,860 - INFO - websocket - WebSocket connection accepted from 127.0.0.1:55758
2025-07-23 23:38:20,863 - INFO - websocket - WebSocket auth: Authenticating user 5B0HV (live)
2025-07-23 23:38:20,929 - WARNING - websocket - Authentication failed for account_number 5B0HV (type live): User not found in correct table.
2025-07-23 23:39:44,016 - INFO - websocket - Redis publisher task cancelled.
2025-07-23 23:39:44,016 - INFO - websocket - Redis publisher task finished.
2025-07-23 23:44:29,499 - INFO - websocket - Redis publisher task started. Publishing to channel 'market_data_updates'.
2025-07-23 23:44:44,896 - INFO - websocket - Redis publisher task cancelled.
2025-07-23 23:44:44,896 - INFO - websocket - Redis publisher task finished.
2025-07-23 23:48:21,724 - INFO - websocket - Redis publisher task started. Publishing to channel 'market_data_updates'.
2025-07-23 23:48:43,269 - INFO - websocket - Redis publisher task cancelled.
2025-07-23 23:48:43,274 - INFO - websocket - Redis publisher task finished.
2025-07-24 01:45:16,433 - INFO - websocket - Redis publisher task started. Publishing to channel 'market_data_updates'.
2025-07-24 01:46:23,448 - INFO - websocket - WebSocket connection attempt from 127.0.0.1:51620
2025-07-24 01:46:23,451 - INFO - websocket - WebSocket connection accepted from 127.0.0.1:51620
2025-07-24 01:46:23,459 - INFO - websocket - WebSocket auth: Authenticating user 5B0HV (live)
2025-07-24 01:46:23,492 - INFO - websocket - User 30: WebSocket initialized with balance=10000.00000000, margin=0
2025-07-24 01:46:24,172 - INFO - websocket - User 30: Successfully updated static orders cache with 0 open orders and 0 pending orders
2025-07-24 01:46:24,457 - INFO - websocket - User 5B0HV: WebSocket connection established successfully
2025-07-24 01:46:29,960 - INFO - websocket - User 5B0HV: WebSocket disconnected
2025-07-24 01:54:51,280 - INFO - websocket - Redis publisher task cancelled.
2025-07-24 01:54:51,280 - INFO - websocket - Redis publisher task finished.
2025-07-24 01:55:47,810 - INFO - websocket - Redis publisher task started. Publishing to channel 'market_data_updates'.
2025-07-24 01:56:51,381 - INFO - websocket - Redis publisher task cancelled.
2025-07-24 01:56:51,381 - INFO - websocket - Redis publisher task finished.
2025-07-24 02:06:45,911 - INFO - websocket - Redis publisher task started. Publishing to channel 'market_data_updates'.
2025-07-24 02:08:15,225 - INFO - websocket - Redis publisher task cancelled.
2025-07-24 02:08:15,225 - INFO - websocket - Redis publisher task finished.
2025-07-24 02:20:05,019 - INFO - websocket - Redis publisher task started. Publishing to channel 'market_data_updates'.
2025-07-24 02:21:54,908 - INFO - websocket - Redis publisher task cancelled.
2025-07-24 02:21:54,908 - INFO - websocket - Redis publisher task finished.
2025-07-24 04:01:24,817 - INFO - websocket - Redis publisher task started. Publishing to channel 'market_data_updates'.
2025-07-24 04:05:12,651 - INFO - websocket - Redis publisher task cancelled.
2025-07-24 04:05:12,651 - INFO - websocket - Redis publisher task finished.
2025-07-24 04:10:32,048 - INFO - websocket - Redis publisher task started. Publishing to channel 'market_data_updates'.
2025-07-24 04:12:33,479 - INFO - websocket - WebSocket connection attempt from 127.0.0.1:60297
2025-07-24 04:12:33,480 - INFO - websocket - WebSocket connection accepted from 127.0.0.1:60297
2025-07-24 04:12:33,485 - INFO - websocket - WebSocket auth: Authenticating user PF5CZ (live)
2025-07-24 04:12:33,529 - INFO - websocket - User 9: WebSocket initialized with balance=8436.59000000, margin=8271.68000000
2025-07-24 04:12:34,928 - INFO - websocket - User 9: Successfully updated static orders cache with 1 open orders and 0 pending orders
2025-07-24 04:12:35,125 - INFO - websocket - User PF5CZ: WebSocket connection established successfully
2025-07-24 04:13:12,439 - INFO - websocket - User PF5CZ: WebSocket disconnected
2025-07-24 04:13:13,369 - INFO - websocket - Redis publisher task cancelled.
2025-07-24 04:13:13,370 - INFO - websocket - Redis publisher task finished.
2025-07-24 04:14:49,868 - INFO - websocket - Redis publisher task started. Publishing to channel 'market_data_updates'.
2025-07-24 04:14:53,895 - INFO - websocket - WebSocket connection attempt from 127.0.0.1:60469
2025-07-24 04:14:53,896 - INFO - websocket - WebSocket connection accepted from 127.0.0.1:60469
2025-07-24 04:14:53,899 - INFO - websocket - WebSocket auth: Authenticating user PF5CZ (live)
2025-07-24 04:14:53,911 - INFO - websocket - User 9: WebSocket initialized with balance=8436.59000000, margin=8271.68000000
2025-07-24 04:14:54,468 - INFO - websocket - User 9: Successfully updated static orders cache with 1 open orders and 0 pending orders
2025-07-24 04:14:54,962 - INFO - websocket - User PF5CZ: WebSocket connection established successfully
2025-07-24 04:15:08,794 - INFO - websocket - User PF5CZ: WebSocket disconnected
2025-07-24 04:15:09,737 - INFO - websocket - Redis publisher task cancelled.
2025-07-24 04:15:09,737 - INFO - websocket - Redis publisher task finished.
2025-07-24 04:15:18,031 - INFO - websocket - Redis publisher task started. Publishing to channel 'market_data_updates'.
2025-07-24 04:15:22,610 - INFO - websocket - WebSocket connection attempt from 127.0.0.1:60527
2025-07-24 04:15:22,611 - INFO - websocket - WebSocket connection accepted from 127.0.0.1:60527
2025-07-24 04:15:22,613 - INFO - websocket - WebSocket auth: Authenticating user PF5CZ (live)
2025-07-24 04:15:22,733 - INFO - websocket - User 9: WebSocket initialized with balance=5.75000000, margin=0
2025-07-24 04:15:30,498 - INFO - websocket - User 9: Successfully updated static orders cache with 0 open orders and 0 pending orders
2025-07-24 04:15:30,717 - INFO - websocket - User PF5CZ: WebSocket connection established successfully
2025-07-24 04:16:08,877 - INFO - websocket - User 9: Successfully updated static orders cache with 0 open orders and 0 pending orders
2025-07-24 04:16:10,072 - INFO - websocket - [WEBSOCKET_DEBUG] User 9: Received ORDER_UPDATE message
2025-07-24 04:16:10,139 - INFO - websocket - [WEBSOCKET_DEBUG] User 9: Received USER_DATA_UPDATE message
2025-07-24 04:16:12,366 - INFO - websocket - User PF5CZ: WebSocket disconnected
2025-07-24 04:16:14,553 - INFO - websocket - Redis publisher task cancelled.
2025-07-24 04:16:14,554 - INFO - websocket - Redis publisher task finished.
2025-07-24 04:27:26,654 - INFO - websocket - Redis publisher task started. Publishing to channel 'market_data_updates'.
2025-07-24 04:27:31,457 - INFO - websocket - WebSocket connection attempt from 127.0.0.1:61557
2025-07-24 04:27:31,459 - INFO - websocket - WebSocket connection accepted from 127.0.0.1:61557
2025-07-24 04:27:31,465 - INFO - websocket - WebSocket auth: Authenticating user PF5CZ (live)
2025-07-24 04:27:31,488 - INFO - websocket - User 9: WebSocket initialized with balance=8436.59000000, margin=8271.68000000
2025-07-24 04:27:32,462 - INFO - websocket - User 9: Successfully updated static orders cache with 1 open orders and 0 pending orders
2025-07-24 04:27:32,925 - INFO - websocket - User PF5CZ: WebSocket connection established successfully
2025-07-24 04:27:39,939 - INFO - websocket - User PF5CZ: WebSocket disconnected
2025-07-24 04:27:47,746 - INFO - websocket - WebSocket connection attempt from 127.0.0.1:61607
2025-07-24 04:27:47,747 - INFO - websocket - WebSocket connection accepted from 127.0.0.1:61607
2025-07-24 04:27:47,750 - INFO - websocket - WebSocket auth: Authenticating user ME4CA (live)
2025-07-24 04:27:47,764 - INFO - websocket - User 31: WebSocket initialized with balance=0E-8, margin=0
2025-07-24 04:27:48,393 - INFO - websocket - User 31: Successfully updated static orders cache with 0 open orders and 0 pending orders
2025-07-24 04:27:48,526 - INFO - websocket - User ME4CA: WebSocket connection established successfully
2025-07-24 04:30:18,348 - INFO - websocket - User ME4CA: WebSocket disconnected
2025-07-24 04:30:19,375 - INFO - websocket - WebSocket connection attempt from 127.0.0.1:61799
2025-07-24 04:30:19,377 - INFO - websocket - WebSocket connection accepted from 127.0.0.1:61799
2025-07-24 04:30:19,380 - INFO - websocket - WebSocket auth: Authenticating user ME4CA (live)
2025-07-24 04:30:19,404 - INFO - websocket - User 31: WebSocket initialized with balance=5000.00000000, margin=0
2025-07-24 04:30:19,832 - INFO - websocket - User 31: Successfully updated static orders cache with 0 open orders and 0 pending orders
2025-07-24 04:30:19,933 - INFO - websocket - User ME4CA: WebSocket connection established successfully
2025-07-24 04:30:25,535 - INFO - websocket - User 31: Successfully updated static orders cache with 0 open orders and 0 pending orders
2025-07-24 04:30:25,912 - INFO - websocket - [WEBSOCKET_DEBUG] User 31: Received ORDER_UPDATE message
2025-07-24 04:30:25,936 - INFO - websocket - [WEBSOCKET_DEBUG] User 31: Received USER_DATA_UPDATE message
2025-07-24 04:32:38,346 - INFO - websocket - User ME4CA: WebSocket disconnected
2025-07-24 04:32:39,726 - INFO - websocket - Redis publisher task cancelled.
2025-07-24 04:32:39,726 - INFO - websocket - Redis publisher task finished.
2025-07-24 04:36:48,009 - INFO - websocket - Redis publisher task started. Publishing to channel 'market_data_updates'.
2025-07-24 04:36:53,573 - INFO - websocket - WebSocket connection attempt from 127.0.0.1:62102
2025-07-24 04:36:53,574 - INFO - websocket - WebSocket connection accepted from 127.0.0.1:62102
2025-07-24 04:36:53,578 - INFO - websocket - WebSocket auth: Authenticating user ME4CA (live)
2025-07-24 04:36:53,590 - INFO - websocket - User 31: WebSocket initialized with balance=5000.00000000, margin=0
2025-07-24 04:36:53,898 - INFO - websocket - User 31: Successfully updated static orders cache with 0 open orders and 0 pending orders
2025-07-24 04:36:53,939 - INFO - websocket - User ME4CA: WebSocket connection established successfully
2025-07-24 04:38:07,615 - INFO - websocket - User ME4CA: WebSocket disconnected
2025-07-24 04:38:09,258 - INFO - websocket - Redis publisher task cancelled.
2025-07-24 04:38:09,258 - INFO - websocket - Redis publisher task finished.
2025-07-24 04:38:31,458 - INFO - websocket - Redis publisher task started. Publishing to channel 'market_data_updates'.
2025-07-24 04:38:37,542 - INFO - websocket - WebSocket connection attempt from 127.0.0.1:62182
2025-07-24 04:38:37,543 - INFO - websocket - WebSocket connection accepted from 127.0.0.1:62182
2025-07-24 04:38:37,545 - INFO - websocket - WebSocket auth: Authenticating user ME4CA (live)
2025-07-24 04:38:37,559 - INFO - websocket - User 31: WebSocket initialized with balance=5000.00000000, margin=0
2025-07-24 04:38:37,751 - INFO - websocket - User 31: Successfully updated static orders cache with 0 open orders and 0 pending orders
2025-07-24 04:38:37,791 - INFO - websocket - User ME4CA: WebSocket connection established successfully
2025-07-24 04:39:16,637 - INFO - websocket - User ME4CA: WebSocket disconnected
2025-07-24 04:39:39,742 - INFO - websocket - WebSocket connection attempt from 127.0.0.1:62245
2025-07-24 04:39:39,743 - INFO - websocket - WebSocket connection accepted from 127.0.0.1:62245
2025-07-24 04:39:39,744 - INFO - websocket - WebSocket auth: Authenticating user PF5CZ (live)
2025-07-24 04:39:39,751 - INFO - websocket - User 9: WebSocket initialized with balance=8436.59000000, margin=8271.68000000
2025-07-24 04:39:40,081 - INFO - websocket - User 9: Successfully updated static orders cache with 1 open orders and 0 pending orders
2025-07-24 04:39:40,128 - INFO - websocket - User PF5CZ: WebSocket connection established successfully
2025-07-24 04:41:42,849 - INFO - websocket - User PF5CZ: WebSocket disconnected
2025-07-24 04:41:44,267 - INFO - websocket - Redis publisher task cancelled.
2025-07-24 04:41:44,268 - INFO - websocket - Redis publisher task finished.
2025-07-24 04:41:48,078 - INFO - websocket - Redis publisher task started. Publishing to channel 'market_data_updates'.
2025-07-24 04:41:48,892 - INFO - websocket - Redis publisher task cancelled.
2025-07-24 04:41:48,892 - INFO - websocket - Redis publisher task finished.
2025-07-24 04:45:54,342 - INFO - websocket - Redis publisher task started. Publishing to channel 'market_data_updates'.
2025-07-24 04:45:58,728 - INFO - websocket - WebSocket connection attempt from 127.0.0.1:62524
2025-07-24 04:45:58,729 - INFO - websocket - WebSocket connection accepted from 127.0.0.1:62524
2025-07-24 04:45:58,732 - INFO - websocket - WebSocket auth: Authenticating user PF5CZ (live)
2025-07-24 04:45:58,749 - INFO - websocket - User 9: WebSocket initialized with balance=8436.59000000, margin=8271.68000000
2025-07-24 04:45:59,360 - INFO - websocket - User 9: Successfully updated static orders cache with 1 open orders and 0 pending orders
2025-07-24 04:45:59,482 - INFO - websocket - User PF5CZ: WebSocket connection established successfully
2025-07-24 04:47:22,681 - INFO - websocket - User PF5CZ: WebSocket disconnected
2025-07-24 04:47:23,426 - INFO - websocket - Redis publisher task cancelled.
2025-07-24 04:47:23,426 - INFO - websocket - Redis publisher task finished.
2025-07-24 05:38:52,896 - INFO - websocket - Redis publisher task started. Publishing to channel 'market_data_updates'.
2025-07-24 05:38:58,829 - INFO - websocket - WebSocket connection attempt from 127.0.0.1:64515
2025-07-24 05:38:58,830 - INFO - websocket - WebSocket connection accepted from 127.0.0.1:64515
2025-07-24 05:38:58,836 - WARNING - websocket - WebSocket auth failed: JWT error for 127.0.0.1:64515: Could not validate credentials
2025-07-24 05:39:04,546 - INFO - websocket - WebSocket connection attempt from 127.0.0.1:64522
2025-07-24 05:39:04,547 - INFO - websocket - WebSocket connection accepted from 127.0.0.1:64522
2025-07-24 05:39:04,549 - WARNING - websocket - WebSocket auth failed: JWT error for 127.0.0.1:64522: Could not validate credentials
2025-07-24 05:39:10,575 - INFO - websocket - WebSocket connection attempt from 127.0.0.1:64526
2025-07-24 05:39:10,575 - INFO - websocket - WebSocket connection accepted from 127.0.0.1:64526
2025-07-24 05:39:10,577 - WARNING - websocket - WebSocket auth failed: JWT error for 127.0.0.1:64526: Could not validate credentials
2025-07-24 05:39:16,543 - INFO - websocket - WebSocket connection attempt from 127.0.0.1:64534
2025-07-24 05:39:16,544 - INFO - websocket - WebSocket connection accepted from 127.0.0.1:64534
2025-07-24 05:39:16,546 - WARNING - websocket - WebSocket auth failed: JWT error for 127.0.0.1:64534: Could not validate credentials
2025-07-24 05:39:22,539 - INFO - websocket - WebSocket connection attempt from 127.0.0.1:64545
2025-07-24 05:39:22,540 - INFO - websocket - WebSocket connection accepted from 127.0.0.1:64545
2025-07-24 05:39:22,541 - WARNING - websocket - WebSocket auth failed: JWT error for 127.0.0.1:64545: Could not validate credentials
2025-07-24 05:39:28,564 - INFO - websocket - WebSocket connection attempt from 127.0.0.1:64557
2025-07-24 05:39:28,565 - INFO - websocket - WebSocket connection accepted from 127.0.0.1:64557
2025-07-24 05:39:28,567 - WARNING - websocket - WebSocket auth failed: JWT error for 127.0.0.1:64557: Could not validate credentials
2025-07-24 05:39:35,054 - INFO - websocket - WebSocket connection attempt from 127.0.0.1:64570
2025-07-24 05:39:35,054 - INFO - websocket - WebSocket connection accepted from 127.0.0.1:64570
2025-07-24 05:39:35,058 - WARNING - websocket - WebSocket auth failed: JWT error for 127.0.0.1:64570: Could not validate credentials
2025-07-24 05:39:40,572 - INFO - websocket - WebSocket connection attempt from 127.0.0.1:64598
2025-07-24 05:39:40,573 - INFO - websocket - WebSocket connection accepted from 127.0.0.1:64598
2025-07-24 05:39:40,576 - WARNING - websocket - WebSocket auth failed: JWT error for 127.0.0.1:64598: Could not validate credentials
2025-07-24 05:39:46,557 - INFO - websocket - WebSocket connection attempt from 127.0.0.1:64608
2025-07-24 05:39:46,558 - INFO - websocket - WebSocket connection accepted from 127.0.0.1:64608
2025-07-24 05:39:46,560 - WARNING - websocket - WebSocket auth failed: JWT error for 127.0.0.1:64608: Could not validate credentials
2025-07-24 05:39:52,564 - INFO - websocket - WebSocket connection attempt from 127.0.0.1:64623
2025-07-24 05:39:52,564 - INFO - websocket - WebSocket connection accepted from 127.0.0.1:64623
2025-07-24 05:39:52,567 - WARNING - websocket - WebSocket auth failed: JWT error for 127.0.0.1:64623: Could not validate credentials
2025-07-24 05:39:58,559 - INFO - websocket - WebSocket connection attempt from 127.0.0.1:64639
2025-07-24 05:39:58,561 - INFO - websocket - WebSocket connection accepted from 127.0.0.1:64639
2025-07-24 05:39:58,564 - WARNING - websocket - WebSocket auth failed: JWT error for 127.0.0.1:64639: Could not validate credentials
2025-07-24 05:40:04,554 - INFO - websocket - WebSocket connection attempt from 127.0.0.1:64642
2025-07-24 05:40:04,555 - INFO - websocket - WebSocket connection accepted from 127.0.0.1:64642
2025-07-24 05:40:04,557 - WARNING - websocket - WebSocket auth failed: JWT error for 127.0.0.1:64642: Could not validate credentials
2025-07-24 05:40:12,623 - INFO - websocket - WebSocket connection attempt from 127.0.0.1:64646
2025-07-24 05:40:12,625 - INFO - websocket - WebSocket connection accepted from 127.0.0.1:64646
2025-07-24 05:40:12,630 - WARNING - websocket - WebSocket auth failed: JWT error for 127.0.0.1:64646: Could not validate credentials
2025-07-24 05:40:18,538 - INFO - websocket - WebSocket connection attempt from 127.0.0.1:64656
2025-07-24 05:40:18,540 - INFO - websocket - WebSocket connection accepted from 127.0.0.1:64656
2025-07-24 05:40:18,543 - WARNING - websocket - WebSocket auth failed: JWT error for 127.0.0.1:64656: Could not validate credentials
2025-07-24 05:40:24,553 - INFO - websocket - WebSocket connection attempt from 127.0.0.1:64659
2025-07-24 05:40:24,554 - INFO - websocket - WebSocket connection accepted from 127.0.0.1:64659
2025-07-24 05:40:24,557 - WARNING - websocket - WebSocket auth failed: JWT error for 127.0.0.1:64659: Could not validate credentials
2025-07-24 05:40:30,554 - INFO - websocket - WebSocket connection attempt from 127.0.0.1:64662
2025-07-24 05:40:30,556 - INFO - websocket - WebSocket connection accepted from 127.0.0.1:64662
2025-07-24 05:40:30,559 - WARNING - websocket - WebSocket auth failed: JWT error for 127.0.0.1:64662: Could not validate credentials
2025-07-24 05:40:36,567 - INFO - websocket - WebSocket connection attempt from 127.0.0.1:64665
2025-07-24 05:40:36,568 - INFO - websocket - WebSocket connection accepted from 127.0.0.1:64665
2025-07-24 05:40:36,571 - WARNING - websocket - WebSocket auth failed: JWT error for 127.0.0.1:64665: Could not validate credentials
2025-07-24 05:40:42,548 - INFO - websocket - WebSocket connection attempt from 127.0.0.1:64671
2025-07-24 05:40:42,549 - INFO - websocket - WebSocket connection accepted from 127.0.0.1:64671
2025-07-24 05:40:42,551 - WARNING - websocket - WebSocket auth failed: JWT error for 127.0.0.1:64671: Could not validate credentials
2025-07-24 05:40:50,275 - INFO - websocket - WebSocket connection attempt from 127.0.0.1:64676
2025-07-24 05:40:50,281 - INFO - websocket - WebSocket connection accepted from 127.0.0.1:64676
2025-07-24 05:40:50,298 - WARNING - websocket - WebSocket auth failed: JWT error for 127.0.0.1:64676: Could not validate credentials
2025-07-24 05:40:56,556 - INFO - websocket - WebSocket connection attempt from 127.0.0.1:64681
2025-07-24 05:40:56,558 - INFO - websocket - WebSocket connection accepted from 127.0.0.1:64681
2025-07-24 05:40:56,560 - WARNING - websocket - WebSocket auth failed: JWT error for 127.0.0.1:64681: Could not validate credentials
2025-07-24 05:41:02,557 - INFO - websocket - WebSocket connection attempt from 127.0.0.1:64684
2025-07-24 05:41:02,559 - INFO - websocket - WebSocket connection accepted from 127.0.0.1:64684
2025-07-24 05:41:02,562 - WARNING - websocket - WebSocket auth failed: JWT error for 127.0.0.1:64684: Could not validate credentials
2025-07-24 05:41:08,552 - INFO - websocket - WebSocket connection attempt from 127.0.0.1:64687
2025-07-24 05:41:08,553 - INFO - websocket - WebSocket connection accepted from 127.0.0.1:64687
2025-07-24 05:41:08,555 - WARNING - websocket - WebSocket auth failed: JWT error for 127.0.0.1:64687: Could not validate credentials
2025-07-24 05:41:14,551 - INFO - websocket - WebSocket connection attempt from 127.0.0.1:64693
2025-07-24 05:41:14,552 - INFO - websocket - WebSocket connection accepted from 127.0.0.1:64693
2025-07-24 05:41:14,555 - WARNING - websocket - WebSocket auth failed: JWT error for 127.0.0.1:64693: Could not validate credentials
2025-07-24 05:41:20,567 - INFO - websocket - WebSocket connection attempt from 127.0.0.1:64702
2025-07-24 05:41:20,568 - INFO - websocket - WebSocket connection accepted from 127.0.0.1:64702
2025-07-24 05:41:20,570 - WARNING - websocket - WebSocket auth failed: JWT error for 127.0.0.1:64702: Could not validate credentials
2025-07-24 05:41:28,126 - INFO - websocket - WebSocket connection attempt from 127.0.0.1:64706
2025-07-24 05:41:28,135 - INFO - websocket - WebSocket connection accepted from 127.0.0.1:64706
2025-07-24 05:41:28,149 - WARNING - websocket - WebSocket auth failed: JWT error for 127.0.0.1:64706: Could not validate credentials
2025-07-24 05:41:33,550 - INFO - websocket - WebSocket connection attempt from 127.0.0.1:64709
2025-07-24 05:41:33,550 - INFO - websocket - WebSocket connection accepted from 127.0.0.1:64709
2025-07-24 05:41:33,551 - WARNING - websocket - WebSocket auth failed: JWT error for 127.0.0.1:64709: Could not validate credentials
2025-07-24 05:41:39,564 - INFO - websocket - WebSocket connection attempt from 127.0.0.1:64711
2025-07-24 05:41:39,566 - INFO - websocket - WebSocket connection accepted from 127.0.0.1:64711
2025-07-24 05:41:39,569 - WARNING - websocket - WebSocket auth failed: JWT error for 127.0.0.1:64711: Could not validate credentials
2025-07-24 05:41:45,560 - INFO - websocket - WebSocket connection attempt from 127.0.0.1:64714
2025-07-24 05:41:45,561 - INFO - websocket - WebSocket connection accepted from 127.0.0.1:64714
2025-07-24 05:41:45,565 - WARNING - websocket - WebSocket auth failed: JWT error for 127.0.0.1:64714: Could not validate credentials
2025-07-24 05:41:51,552 - INFO - websocket - WebSocket connection attempt from 127.0.0.1:64720
2025-07-24 05:41:51,554 - INFO - websocket - WebSocket connection accepted from 127.0.0.1:64720
2025-07-24 05:41:51,556 - WARNING - websocket - WebSocket auth failed: JWT error for 127.0.0.1:64720: Could not validate credentials
2025-07-24 05:41:57,509 - INFO - websocket - Redis publisher task cancelled.
2025-07-24 05:41:57,510 - INFO - websocket - Redis publisher task finished.
2025-07-24 05:43:54,559 - INFO - websocket - Redis publisher task started. Publishing to channel 'market_data_updates'.
2025-07-24 05:43:55,888 - INFO - websocket - WebSocket connection attempt from 127.0.0.1:64911
2025-07-24 05:43:55,888 - INFO - websocket - WebSocket connection accepted from 127.0.0.1:64911
2025-07-24 05:43:55,891 - WARNING - websocket - WebSocket auth failed: JWT error for 127.0.0.1:64911: Could not validate credentials
2025-07-24 05:44:03,764 - INFO - websocket - WebSocket connection attempt from 127.0.0.1:64930
2025-07-24 05:44:03,765 - INFO - websocket - WebSocket connection accepted from 127.0.0.1:64930
2025-07-24 05:44:03,769 - WARNING - websocket - WebSocket auth failed: JWT error for 127.0.0.1:64930: Could not validate credentials
2025-07-24 05:44:09,556 - INFO - websocket - WebSocket connection attempt from 127.0.0.1:64937
2025-07-24 05:44:09,557 - INFO - websocket - WebSocket connection accepted from 127.0.0.1:64937
2025-07-24 05:44:09,560 - WARNING - websocket - WebSocket auth failed: JWT error for 127.0.0.1:64937: Could not validate credentials
2025-07-24 05:44:15,555 - INFO - websocket - WebSocket connection attempt from 127.0.0.1:64943
2025-07-24 05:44:15,560 - INFO - websocket - WebSocket connection accepted from 127.0.0.1:64943
2025-07-24 05:44:15,566 - WARNING - websocket - WebSocket auth failed: JWT error for 127.0.0.1:64943: Could not validate credentials
2025-07-24 05:44:21,550 - INFO - websocket - WebSocket connection attempt from 127.0.0.1:64945
2025-07-24 05:44:21,551 - INFO - websocket - WebSocket connection accepted from 127.0.0.1:64945
2025-07-24 05:44:21,552 - WARNING - websocket - WebSocket auth failed: JWT error for 127.0.0.1:64945: Could not validate credentials
2025-07-24 05:44:27,539 - INFO - websocket - WebSocket connection attempt from 127.0.0.1:64948
2025-07-24 05:44:27,540 - INFO - websocket - WebSocket connection accepted from 127.0.0.1:64948
2025-07-24 05:44:27,541 - WARNING - websocket - WebSocket auth failed: JWT error for 127.0.0.1:64948: Could not validate credentials
2025-07-24 05:44:33,552 - INFO - websocket - WebSocket connection attempt from 127.0.0.1:64951
2025-07-24 05:44:33,553 - INFO - websocket - WebSocket connection accepted from 127.0.0.1:64951
2025-07-24 05:44:33,555 - WARNING - websocket - WebSocket auth failed: JWT error for 127.0.0.1:64951: Could not validate credentials
2025-07-24 05:44:39,557 - INFO - websocket - WebSocket connection attempt from 127.0.0.1:64956
2025-07-24 05:44:39,557 - INFO - websocket - WebSocket connection accepted from 127.0.0.1:64956
2025-07-24 05:44:39,558 - WARNING - websocket - WebSocket auth failed: JWT error for 127.0.0.1:64956: Could not validate credentials
2025-07-24 05:44:45,551 - INFO - websocket - WebSocket connection attempt from 127.0.0.1:64961
2025-07-24 05:44:45,552 - INFO - websocket - WebSocket connection accepted from 127.0.0.1:64961
2025-07-24 05:44:45,553 - WARNING - websocket - WebSocket auth failed: JWT error for 127.0.0.1:64961: Could not validate credentials
2025-07-24 05:44:51,548 - INFO - websocket - WebSocket connection attempt from 127.0.0.1:64974
2025-07-24 05:44:51,548 - INFO - websocket - WebSocket connection accepted from 127.0.0.1:64974
2025-07-24 05:44:51,550 - WARNING - websocket - WebSocket auth failed: JWT error for 127.0.0.1:64974: Could not validate credentials
2025-07-24 05:44:57,560 - INFO - websocket - WebSocket connection attempt from 127.0.0.1:65007
2025-07-24 05:44:57,560 - INFO - websocket - WebSocket connection accepted from 127.0.0.1:65007
2025-07-24 05:44:57,561 - WARNING - websocket - WebSocket auth failed: JWT error for 127.0.0.1:65007: Could not validate credentials
2025-07-24 05:45:03,599 - INFO - websocket - WebSocket connection attempt from 127.0.0.1:65014
2025-07-24 05:45:03,600 - INFO - websocket - WebSocket connection accepted from 127.0.0.1:65014
2025-07-24 05:45:03,602 - WARNING - websocket - WebSocket auth failed: JWT error for 127.0.0.1:65014: Could not validate credentials
2025-07-24 05:45:09,552 - INFO - websocket - WebSocket connection attempt from 127.0.0.1:65021
2025-07-24 05:45:09,552 - INFO - websocket - WebSocket connection accepted from 127.0.0.1:65021
2025-07-24 05:45:09,554 - WARNING - websocket - WebSocket auth failed: JWT error for 127.0.0.1:65021: Could not validate credentials
2025-07-24 05:45:16,085 - INFO - websocket - WebSocket connection attempt from 127.0.0.1:65028
2025-07-24 05:45:16,086 - INFO - websocket - WebSocket connection accepted from 127.0.0.1:65028
2025-07-24 05:45:16,087 - WARNING - websocket - WebSocket auth failed: JWT error for 127.0.0.1:65028: Could not validate credentials
2025-07-24 05:45:21,591 - INFO - websocket - WebSocket connection attempt from 127.0.0.1:65032
2025-07-24 05:45:21,591 - INFO - websocket - WebSocket connection accepted from 127.0.0.1:65032
2025-07-24 05:45:21,592 - WARNING - websocket - WebSocket auth failed: JWT error for 127.0.0.1:65032: Could not validate credentials
2025-07-24 05:45:27,544 - INFO - websocket - WebSocket connection attempt from 127.0.0.1:65037
2025-07-24 05:45:27,544 - INFO - websocket - WebSocket connection accepted from 127.0.0.1:65037
2025-07-24 05:45:27,545 - WARNING - websocket - WebSocket auth failed: JWT error for 127.0.0.1:65037: Could not validate credentials
2025-07-24 05:45:33,562 - INFO - websocket - WebSocket connection attempt from 127.0.0.1:65039
2025-07-24 05:45:33,563 - INFO - websocket - WebSocket connection accepted from 127.0.0.1:65039
2025-07-24 05:45:33,565 - WARNING - websocket - WebSocket auth failed: JWT error for 127.0.0.1:65039: Could not validate credentials
2025-07-24 05:45:39,567 - INFO - websocket - WebSocket connection attempt from 127.0.0.1:65045
2025-07-24 05:45:39,568 - INFO - websocket - WebSocket connection accepted from 127.0.0.1:65045
2025-07-24 05:45:39,569 - WARNING - websocket - WebSocket auth failed: JWT error for 127.0.0.1:65045: Could not validate credentials
2025-07-24 05:45:45,567 - INFO - websocket - WebSocket connection attempt from 127.0.0.1:65048
2025-07-24 05:45:45,568 - INFO - websocket - WebSocket connection accepted from 127.0.0.1:65048
2025-07-24 05:45:45,569 - WARNING - websocket - WebSocket auth failed: JWT error for 127.0.0.1:65048: Could not validate credentials
2025-07-24 05:45:53,301 - INFO - websocket - WebSocket connection attempt from 127.0.0.1:65055
2025-07-24 05:45:53,301 - INFO - websocket - WebSocket connection accepted from 127.0.0.1:65055
2025-07-24 05:45:53,303 - WARNING - websocket - WebSocket auth failed: JWT error for 127.0.0.1:65055: Could not validate credentials
2025-07-24 05:45:59,558 - INFO - websocket - WebSocket connection attempt from 127.0.0.1:65060
2025-07-24 05:45:59,559 - INFO - websocket - WebSocket connection accepted from 127.0.0.1:65060
2025-07-24 05:45:59,560 - WARNING - websocket - WebSocket auth failed: JWT error for 127.0.0.1:65060: Could not validate credentials
2025-07-24 05:46:05,555 - INFO - websocket - WebSocket connection attempt from 127.0.0.1:65063
2025-07-24 05:46:05,556 - INFO - websocket - WebSocket connection accepted from 127.0.0.1:65063
2025-07-24 05:46:05,558 - WARNING - websocket - WebSocket auth failed: JWT error for 127.0.0.1:65063: Could not validate credentials
2025-07-24 05:46:09,244 - INFO - websocket - Redis publisher task cancelled.
2025-07-24 05:46:09,245 - INFO - websocket - Redis publisher task finished.
2025-07-24 05:48:26,663 - INFO - websocket - Redis publisher task started. Publishing to channel 'market_data_updates'.
2025-07-24 05:48:27,605 - INFO - websocket - WebSocket connection attempt from 127.0.0.1:65186
2025-07-24 05:48:27,606 - INFO - websocket - WebSocket connection accepted from 127.0.0.1:65186
2025-07-24 05:48:27,609 - WARNING - websocket - WebSocket auth failed: JWT error for 127.0.0.1:65186: Could not validate credentials
2025-07-24 05:48:34,416 - INFO - websocket - WebSocket connection attempt from 127.0.0.1:65213
2025-07-24 05:48:34,417 - INFO - websocket - WebSocket connection accepted from 127.0.0.1:65213
2025-07-24 05:48:34,422 - WARNING - websocket - WebSocket auth failed: JWT error for 127.0.0.1:65213: Could not validate credentials
2025-07-24 05:48:40,553 - INFO - websocket - WebSocket connection attempt from 127.0.0.1:65219
2025-07-24 05:48:40,554 - INFO - websocket - WebSocket connection accepted from 127.0.0.1:65219
2025-07-24 05:48:40,556 - WARNING - websocket - WebSocket auth failed: JWT error for 127.0.0.1:65219: Could not validate credentials
2025-07-24 05:48:46,551 - INFO - websocket - WebSocket connection attempt from 127.0.0.1:65224
2025-07-24 05:48:46,552 - INFO - websocket - WebSocket connection accepted from 127.0.0.1:65224
2025-07-24 05:48:46,556 - WARNING - websocket - WebSocket auth failed: JWT error for 127.0.0.1:65224: Could not validate credentials
2025-07-24 05:48:52,591 - INFO - websocket - WebSocket connection attempt from 127.0.0.1:65228
2025-07-24 05:48:52,593 - INFO - websocket - WebSocket connection accepted from 127.0.0.1:65228
2025-07-24 05:48:52,599 - WARNING - websocket - WebSocket auth failed: JWT error for 127.0.0.1:65228: Could not validate credentials
2025-07-24 05:48:58,561 - INFO - websocket - WebSocket connection attempt from 127.0.0.1:65233
2025-07-24 05:48:58,561 - INFO - websocket - WebSocket connection accepted from 127.0.0.1:65233
2025-07-24 05:48:58,567 - WARNING - websocket - WebSocket auth failed: JWT error for 127.0.0.1:65233: Could not validate credentials
2025-07-24 05:49:04,569 - INFO - websocket - WebSocket connection attempt from 127.0.0.1:65238
2025-07-24 05:49:04,570 - INFO - websocket - WebSocket connection accepted from 127.0.0.1:65238
2025-07-24 05:49:04,572 - WARNING - websocket - WebSocket auth failed: JWT error for 127.0.0.1:65238: Could not validate credentials
2025-07-24 05:49:10,592 - INFO - websocket - WebSocket connection attempt from 127.0.0.1:65242
2025-07-24 05:49:10,593 - INFO - websocket - WebSocket connection accepted from 127.0.0.1:65242
2025-07-24 05:49:10,596 - WARNING - websocket - WebSocket auth failed: JWT error for 127.0.0.1:65242: Could not validate credentials
2025-07-24 05:49:16,581 - INFO - websocket - WebSocket connection attempt from 127.0.0.1:65245
2025-07-24 05:49:16,583 - INFO - websocket - WebSocket connection accepted from 127.0.0.1:65245
2025-07-24 05:49:16,586 - WARNING - websocket - WebSocket auth failed: JWT error for 127.0.0.1:65245: Could not validate credentials
2025-07-24 05:49:22,565 - INFO - websocket - WebSocket connection attempt from 127.0.0.1:65250
2025-07-24 05:49:22,567 - INFO - websocket - WebSocket connection accepted from 127.0.0.1:65250
2025-07-24 05:49:22,568 - WARNING - websocket - WebSocket auth failed: JWT error for 127.0.0.1:65250: Could not validate credentials
2025-07-24 05:49:54,093 - INFO - websocket - Redis publisher task cancelled.
2025-07-24 05:49:54,093 - INFO - websocket - Redis publisher task finished.
2025-07-24 05:51:29,328 - INFO - websocket - Redis publisher task started. Publishing to channel 'market_data_updates'.
2025-07-24 05:52:41,333 - INFO - websocket - Redis publisher task cancelled.
2025-07-24 05:52:41,333 - INFO - websocket - Redis publisher task finished.
